Workbook

Sheet Objectif
A1: OBJECTIF ANNUEL
C2: Total
A3: Période | C3: 2025 | D3: 2026 | F3: Objectif | G3: % atteint | K3: Vente de l'année | L3: =D16 -> 70424.56
A4: JANVIER | D4: =Janvier!B4 -> 8701.44 | F4: =E21+I21+M21+Q21+U21+Y21 -> 13500 | G4: =D4/F4 -> 0.64455111
A5: FÉVRIER | D5: ='Février'!B4 -> 11067.07 | F5: =E22+I22+M22+Q22+U22+Y22 -> 23250 | G5: =D5/F5 -> 0.47600301 | K5: Objectif de vente annuel | L5: =E33+I33+M33+Q33+U33+Y33 -> 300000
A6: MARS | D6: =Mars!B4 -> 20331.61 | F6: =E23+I23+M23+Q23+U23+Y23 -> 27000 | G6: =D6/F6 -> 0.75302259
A7: AVRIL | D7: =Avril!B4 -> 30324.44 | F7: =E24+I24+M24+Q24+U24+Y24 -> 24750 | G7: =D7/F7 -> 1.2252299 | K7: % atteint | L7: =L3/L5 -> 0.23474853
A8: MAI | D8: =Mai!B4 -> 0 | F8: =E25+I25+M25+Q25+U25+Y25 -> 36000 | G8: =D8/F8 -> 0
A9: JUIN | D9: =Juin!B4 -> 0 | F9: =E26+I26+M26+Q26+U26+Y26 -> 21000 | G9: =D9/F9 -> 0
A10: JUILLET | D10: =Juillet!B4 -> 0 | F10: =E27+I27+M27+Q27+U27+Y27 -> 21750 | G10: =D10/F10 -> 0
A11: AOÛT | D11: ='Août'!B4 -> 0 | F11: =E28+I28+M28+Q28+U28+Y28 -> 24000 | G11: =D11/F11 -> 0
A12: SEPTEMBRE | D12: =Septembre!B4 -> 0 | F12: =E29+I29+M29+Q29+U29+Y29 -> 33000 | G12: =D12/F12 -> 0
A13: OCTOBRE | D13: =Octobre!B4 -> 0 | F13: =E30+I30+M30+Q30+U30+Y30 -> 34500 | G13: =D13/F13 -> 0
A14: NOVEMBRE | D14: =Novembre!B4 -> 0 | F14: =E31+I31+M31+Q31+U31+Y31 -> 30000 | G14: =D14/F14 -> 0
A15: DÉCEMBRE | D15: ='Décembre'!B4 -> 0 | F15: =E32+I32+M32+Q32+U32+Y32 -> 11250 | G15: =D15/F15 -> 0
A16: Total | C16: =SUM(C4:C15) -> 0 | D16: =SUM(D4:D15) -> 70424.56 | F16: =SUM(F4:F15) -> 300000 | G16: =D16/F16 -> 0.23474853
C19: MULTI-ANNONCEURS | G19: PROMOTIONNEL | K19: DIST. PUBLICITAIRE SOLO | O19: NUMÉRIQUE | S19: APPLICATION | W19: SERVICES IA
A20: Période | C20: 2025 | D20: 2026 | E20: Objectif | F20: % atteint | G20: 2025 | H20: 2026 | I20: Objectif | J20: % atteint | K20: 2025 | L20: 2026 | M20: Objectif | N20: % atteint | O20: 2025 | P20: 2026 | Q20: Objectif | R20: % atteint | S20: 2025 | T20: 2026 | U20: Objectif | V20: % atteint | W20: 2025 | X20: 2026 | Y20: Objectif | Z20: % atteint
A21: JANVIER | D21: =Janvier!C4 -> 0 | F21: =D21/E21 -> #DIV/0! | H21: =Janvier!D4 -> 8701.44 | I21: 13500 | J21: =H21/I21 -> 0.64455111 | L21: =Janvier!E4 -> 0 | N21: =L21/M21 -> #DIV/0! | P21: =Janvier!F4 -> 0 | R21: =P21/Q21 -> #DIV/0! | T21: =Janvier!G4 -> 0 | V21: =T21/U21 -> #DIV/0! | X21: =Janvier!K4 | Z21: =X21/Y21 -> #DIV/0!
A22: FÉVRIER | D22: ='Février'!C4 -> 0 | F22: =D22/E22 -> #DIV/0! | H22: ='Février'!D4 -> 11067.07 | I22: 23250 | J22: =H22/I22 -> 0.47600301 | L22: ='Février'!E4 -> 0 | N22: =L22/M22 -> #DIV/0! | P22: ='Février'!F4 -> 0 | R22: =P22/Q22 -> #DIV/0! | T22: ='Février'!G4 -> 0 | V22: =T22/U22 -> #DIV/0! | X22: ='Février'!K4 | Z22: =X22/Y22 -> #DIV/0!
A23: MARS | D23: =Mars!C4 -> 0 | F23: =D23/E23 -> #DIV/0! | H23: =Mars!D4 -> 20331.61 | I23: 27000 | J23: =H23/I23 -> 0.75302259 | L23: =Mars!E4 -> 0 | N23: =L23/M23 -> #DIV/0! | P23: =Mars!F4 -> 0 | R23: =P23/Q23 -> #DIV/0! | T23: =Mars!G4 -> 0 | V23: =T23/U23 -> #DIV/0! | X23: =Mars!K4 | Z23: =X23/Y23 -> #DIV/0!
A24: AVRIL | D24: =Avril!C4 -> 0 | F24: =D24/E24 -> #DIV/0! | H24: =Avril!D4 -> 30324.44 | I24: 24750 | J24: =H24/I24 -> 1.2252299 | L24: =Avril!E4 -> 0 | N24: =L24/M24 -> #DIV/0! | P24: =Avril!F4 -> 0 | R24: =P24/Q24 -> #DIV/0! | T24: =Avril!G4 -> 0 | V24: =T24/U24 -> #DIV/0! | X24: =Avril!K4 | Z24: =X24/Y24 -> #DIV/0!
A25: MAI | D25: =Mai!C4 -> 0 | F25: =D25/E25 -> #DIV/0! | H25: =Mai!D4 -> 0 | I25: 36000 | J25: =H25/I25 -> 0 | L25: =Mai!E4 -> 0 | N25: =L25/M25 -> #DIV/0! | P25: =Mai!F4 -> 0 | R25: =P25/Q25 -> #DIV/0! | T25: =Mai!G4 -> 0 | V25: =T25/U25 -> #DIV/0! | X25: =Mai!K4 | Z25: =X25/Y25 -> #DIV/0!
A26: JUIN | D26: =Juin!C4 -> 0 | F26: =D26/E26 -> #DIV/0! | H26: =Juin!D4 -> 0 | I26: 21000 | J26: =H26/I26 -> 0 | L26: =Juin!E4 -> 0 | N26: =L26/M26 -> #DIV/0! | P26: =Juin!F4 -> 0 | R26: =P26/Q26 -> #DIV/0! | T26: =Juin!G4 -> 0 | V26: =T26/U26 -> #DIV/0! | X26: =Juin!K4 | Z26: =X26/Y26 -> #DIV/0!
A27: JUILLET | D27: =Juillet!C4 -> 0 | F27: =D27/E27 -> #DIV/0! | H27: =Juillet!D4 -> 0 | I27: 21750 | J27: =H27/I27 -> 0 | L27: =Juillet!E4 -> 0 | N27: =L27/M27 -> #DIV/0! | P27: =Juillet!F4 -> 0 | R27: =P27/Q27 -> #DIV/0! | T27: =Juillet!G4 -> 0 | V27: =T27/U27 -> #DIV/0! | X27: =Juillet!K4 | Z27: =X27/Y27 -> #DIV/0!
A28: AOÛT | D28: ='Août'!C4 -> 0 | F28: =D28/E28 -> #DIV/0! | H28: ='Août'!D4 -> 0 | I28: 24000 | J28: =H28/I28 -> 0 | L28: ='Août'!E4 -> 0 | N28: =L28/M28 -> #DIV/0! | P28: ='Août'!F4 -> 0 | R28: =P28/Q28 -> #DIV/0! | T28: ='Août'!G4 -> 0 | V28: =T28/U28 -> #DIV/0! | X28: ='Août'!K4 | Z28: =X28/Y28 -> #DIV/0!
A29: SEPTEMBRE | D29: =Septembre!C4 -> 0 | F29: =D29/E29 -> #DIV/0! | H29: =Septembre!D4 -> 0 | I29: 33000 | J29: =H29/I29 -> 0 | L29: =Septembre!E4 -> 0 | N29: =L29/M29 -> #DIV/0! | P29: =Septembre!F4 -> 0 | R29: =P29/Q29 -> #DIV/0! | T29: =Septembre!G4 -> 0 | V29: =T29/U29 -> #DIV/0! | X29: =Septembre!K4 | Z29: =X29/Y29 -> #DIV/0!
A30: OCTOBRE | D30: =Octobre!C4 -> 0 | F30: =D30/E30 -> #DIV/0! | H30: =Octobre!D4 -> 0 | I30: 34500 | J30: =H30/I30 -> 0 | L30: =Octobre!E4 -> 0 | N30: =L30/M30 -> #DIV/0! | P30: =Octobre!F4 -> 0 | R30: =P30/Q30 -> #DIV/0! | T30: =Octobre!G4 -> 0 | V30: =T30/U30 -> #DIV/0! | X30: =Octobre!K4 | Z30: =X30/Y30 -> #DIV/0!
A31: NOVEMBRE | D31: =Novembre!C4 -> 0 | F31: =D31/E31 -> #DIV/0! | H31: =Novembre!D4 -> 0 | I31: 30000 | J31: =H31/I31 -> 0 | L31: =Novembre!E4 -> 0 | N31: =L31/M31 -> #DIV/0! | P31: =Novembre!F4 -> 0 | R31: =P31/Q31 -> #DIV/0! | T31: =Novembre!G4 -> 0 | V31: =T31/U31 -> #DIV/0! | X31: =Novembre!K4 | Z31: =X31/Y31 -> #DIV/0!
A32: DÉCEMBRE | D32: ='Décembre'!C4 -> 0 | F32: =D32/E32 -> #DIV/0! | H32: ='Décembre'!D4 -> 0 | I32: 11250 | J32: =H32/I32 -> 0 | L32: ='Décembre'!E4 -> 0 | N32: =L32/M32 -> #DIV/0! | P32: ='Décembre'!F4 -> 0 | R32: =P32/Q32 -> #DIV/0! | T32: ='Décembre'!G4 -> 0 | V32: =T32/U32 -> #DIV/0! | X32: ='Décembre'!K4 | Z32: =X32/Y32 -> #DIV/0!
A33: Total | C33: =SUM(C21:C32) -> 0 | D33: =SUM(D21:D32) -> 0 | E33: =SUM(E21:E32) -> 0 | F33: =D33/E33 -> #DIV/0! | G33: =SUM(G21:G32) -> 0 | H33: =SUM(H21:H32) -> 70424.56 | I33: =SUM(I21:I32) -> 300000 | J33: =H33/I33 -> 0.23474853 | K33: =SUM(K21:K32) -> 0 | L33: =SUM(L21:L32) -> 0 | M33: =SUM(M21:M32) -> 0 | N33: =L33/M33 -> #DIV/0! | O33: =SUM(O21:O32) -> 0 | P33: =SUM(P21:P32) -> 0 | Q33: =SUM(Q21:Q32) -> 0 | R33: =P33/Q33 -> #DIV/0! | S33: =SUM(S21:S32) -> 0 | T33: =SUM(T21:T32) -> 0 | U33: =SUM(U21:U32) -> 0 | V33: =T33/U33 -> #DIV/0! | W33: =SUM(W21:W32) -> 0 | X33: =SUM(X21:X32) -> 0 | Y33: =SUM(Y21:Y32) -> 0 | Z33: =X33/Y33 -> #DIV/0!

Sheet Janvier
B1: Totaux | C1: MÉDIA MULTI-ANNONCEURS | D1: PROMOTIONNEL | E1: DIST. PUBLICITAIRE SOLO | F1: NUMÉRIQUE | G1: APPLICATION | H1: SERVICES IA
A2: Commission | B2: =SUM(G7:G962) -> 870.144 | C2: =SUMIF(F8:F960,"MÉDIA MULTI-ANNONCEURS",G8:G960) -> 0 | D2: =SUMIF(F8:F960,"PROMOTIONNEL",G8:G960) -> 870.144 | E2: =SUMIF(F8:F960,"DIST. PUBLICITAIRE SOLO",G8:G960) -> 0 | F2: =SUMIF(F8:F960,"AGENCE PUB",G8:G960) -> 0 | G2: =SUMIF(F8:F960,"AGENCE WEB",G8:G960) -> 0 | H2: =SUMIF(F8:F960,"SERVICES IA",G8:G960) -> 0
A4: Vente | B4: =SUM(B8:B962) -> 8701.44 | C4: =SUMIF(F8:F960,"MÉDIA MULTI-ANNONCEURS",B8:B960) -> 0 | D4: =SUMIF(F8:F960,"PROMOTIONNEL",B8:B960) -> 8701.44 | E4: =SUMIF(F8:F960,"DIST. PUBLICITAIRE SOLO",B8:B960) -> 0 | F4: =SUMIF(F8:F960,"AGENCE PUB",B8:B960) -> 0 | G4: =SUMIF(F8:F960,"AGENCE WEB",B8:B960) -> 0 | H4: =SUMIF(F8:F960,"SERVICES IA",B8:B960) -> 0
A7: CLIENT | B7: TOTAL (AVANT TAXES) | C7: # FACTURE | D7: DATE | E7: REPRÉSENTANT | F7: DÉPARTEMENT | G7: COMMISSION
A8: CPE Fleur de Papier | B8: 912.94 | C8: QC-019165 | D8: 46031 | E8: Morgane Owczarzak | F8: PROMOTIONNEL | G8: =B8*0.1 -> 91.294
A9: CPE Fleur de Papier | B9: 60.98 | C9: QC-019164 | D9: 46031 | E9: Morgane Owczarzak | F9: PROMOTIONNEL | G9: =B9*0.1 -> 6.098
A10: Ça l'air cochon | B10: 2005.07 | C10: QC-019163 | D10: 46031 | E10: Morgane Owczarzak | F10: PROMOTIONNEL | G10: =B10*0.1 -> 200.507
A11: Alarme St Jérôme | B11: 60 | C11: QC-019170 | D11: 46035 | E11: Morgane Owczarzak | F11: PROMOTIONNEL | G11: =B11*0.1 -> 6
A12: SDQL | B12: 744.59 | C12: QC-019167 | D12: 46034 | E12: Morgane Owczarzak | F12: PROMOTIONNEL | G12: =B12*0.1 -> 74.459
A13: Run n Talk - ULaval | B13: 1615 | C13: QC-019275 | D13: 46052 | E13: Morgane Owczarzak | F13: PROMOTIONNEL | G13: =B13*0.1 -> 161.5
A14: 20e Groupe Scout du Triangle | B14: 2025 | C14: QC-019266 | D14: 46050 | E14: Morgane Owczarzak | F14: PROMOTIONNEL | G14: =B14*0.1 -> 202.5
A15: Habitations Denali | B15: 1277.86 | C15: QC-019264 | D15: 46050 | E15: Morgane Owczarzak | F15: PROMOTIONNEL | G15: =B15*0.1 -> 127.786
G16: =B16*0.1 -> 0
G17: =B17*0.1 -> 0
G18: =B18*0.1 -> 0
G19: =B19*0.1 -> 0
G20: =B20*0.1 -> 0
G21: =B21*0.1 -> 0
G22: =B22*0.1 -> 0
G23: =B23*0.1 -> 0
G24: =B24*0.1 -> 0
G25: =B25*0.1 -> 0
G26: =B26*0.1 -> 0
G27: =B27*0.1 -> 0
... G166: =B166*0.1 -> 0
G167: =B167*0.05 -> 0
G168: =B168*0.05 -> 0
G169: =B169*0.05 -> 0
G170: =B170*0.05 -> 0
G171: =B171*0.05 -> 0
G172: =B172*0.05 -> 0
G173: =B173*0.05 -> 0
G174: =B174*0.05 -> 0
G175: =B175*0.05 -> 0
G176: =B176*0.05 -> 0
G177: =B177*0.05 -> 0
G178: =B178*0.05 -> 0
... G212: =B212*0.05 -> 0

Sheet Février
B1: Totaux | C1: MÉDIA MULTI-ANNONCEURS | D1: PROMOTIONNEL | E1: DIST. PUBLICITAIRE SOLO | F1: NUMÉRIQUE | G1: APPLICATION | H1: SERVICES IA
A2: Commission | B2: =SUM(G7:G962) -> 1106.707 | C2: =SUMIF(F8:F960,"MÉDIA MULTI-ANNONCEURS",G8:G960) -> 0 | D2: =SUMIF(F8:F960,"PROMOTIONNEL",G8:G960) -> 1106.707 | E2: =SUMIF(F8:F960,"DIST. PUBLICITAIRE SOLO",G8:G960) -> 0 | F2: =SUMIF(F8:F960,"AGENCE PUB",G8:G960) -> 0 | G2: =SUMIF(F8:F960,"AGENCE WEB",G8:G960) -> 0 | H2: =SUMIF(F8:F960,"SERVICES IA",G8:G960) -> 0
A4: Vente | B4: =SUM(B8:B962) -> 11067.07 | C4: =SUMIF(F8:F960,"MÉDIA MULTI-ANNONCEURS",B8:B960) -> 0 | D4: =SUMIF(F8:F960,"PROMOTIONNEL",B8:B960) -> 11067.07 | E4: =SUMIF(F8:F960,"DIST. PUBLICITAIRE SOLO",B8:B960) -> 0 | F4: =SUMIF(F8:F960,"AGENCE PUB",B8:B960) -> 0 | G4: =SUMIF(F8:F960,"AGENCE WEB",B8:B960) -> 0 | H4: =SUMIF(F8:F960,"SERVICES IA",B8:B960) -> 0
A7: CLIENT | B7: TOTAL (AVANT TAXES) | C7: # FACTURE | D7: DATE | E7: REPRÉSENTANT | F7: DÉPARTEMENT | G7: COMMISSION
A8: Irrigation CM | B8: 1728.93 | C8: QC-019446 | D8: 46066 | E8: Morgane Owczarzak | F8: PROMOTIONNEL | G8: =B8*0.1 -> 172.893
A9: Strana Talent | B9: 5375 | C9: QC-019417 | D9: 46062 | E9: Morgane Owczarzak | F9: PROMOTIONNEL | G9: =B9*0.1 -> 537.5
A10: Alarme St Jérôme | B10: -60 | C10: CN-01077 | D10: 46063 | E10: Morgane Owczarzak | F10: PROMOTIONNEL | G10: =B10*0.1 -> -6
A11: Alarme St Jérôme | B11: -1063.74 | C11: CN-01076 | D11: 46063 | E11: Morgane Owczarzak | F11: PROMOTIONNEL | G11: =B11*0.1 -> -106.374
A12: Irrigation CM | B12: 63.26 | C12: QC-019465 | D12: 46071 | E12: Morgane Owczarzak | F12: PROMOTIONNEL | G12: =B12*0.1 -> 6.326
A13: Wampole, une division de Corporation JAMP Pharma | B13: 325 | C13: QC-019514 | D13: 46079 | E13: Morgane Owczarzak | F13: PROMOTIONNEL | G13: =B13*0.1 -> 32.5
A14: Pro Pac Industries | B14: 851.02 | C14: QC-019504 | D14: 46077 | E14: Morgane Owczarzak | F14: PROMOTIONNEL | G14: =B14*0.1 -> 85.102
A15: FKL Construction | B15: 3847.6 | C15: QC-019502 | D15: 46077 | E15: Morgane Owczarzak | F15: PROMOTIONNEL | G15: =B15*0.1 -> 384.76
G16: =B16*0.1 -> 0
G17: =B17*0.1 -> 0
G18: =B18*0.1 -> 0
G19: =B19*0.1 -> 0
G20: =B20*0.1 -> 0
G21: =B21*0.1 -> 0
G22: =B22*0.1 -> 0
G23: =B23*0.1 -> 0
G24: =B24*0.1 -> 0
G25: =B25*0.1 -> 0
G26: =B26*0.1 -> 0
G27: =B27*0.1 -> 0
... G166: =B166*0.1 -> 0
G167: =B167*0.05 -> 0
G168: =B168*0.05 -> 0
G169: =B169*0.05 -> 0
G170: =B170*0.05 -> 0
G171: =B171*0.05 -> 0
G172: =B172*0.05 -> 0
G173: =B173*0.05 -> 0
G174: =B174*0.05 -> 0
G175: =B175*0.05 -> 0
G176: =B176*0.05 -> 0
G177: =B177*0.05 -> 0
G178: =B178*0.05 -> 0
... G212: =B212*0.05 -> 0

Sheet Mars
B1: Totaux | C1: MÉDIA MULTI-ANNONCEURS | D1: PROMOTIONNEL | E1: DIST. PUBLICITAIRE SOLO | F1: NUMÉRIQUE | G1: APPLICATION | H1: SERVICES IA
A2: Commission | B2: =SUM(G7:G962) -> 2033.161 | C2: =SUMIF(F8:F960,"MÉDIA MULTI-ANNONCEURS",G8:G960) -> 0 | D2: =SUMIF(F8:F960,"PROMOTIONNEL",G8:G960) -> 2033.161 | E2: =SUMIF(F8:F960,"DIST. PUBLICITAIRE SOLO",G8:G960) -> 0 | F2: =SUMIF(F8:F960,"AGENCE PUB",G8:G960) -> 0 | G2: =SUMIF(F8:F960,"AGENCE WEB",G8:G960) -> 0 | H2: =SUMIF(F8:F960,"SERVICES IA",G8:G960) -> 0
A4: Vente | B4: =SUM(B8:B962) -> 20331.61 | C4: =SUMIF(F8:F960,"MÉDIA MULTI-ANNONCEURS",B8:B960) -> 0 | D4: =SUMIF(F8:F960,"PROMOTIONNEL",B8:B960) -> 20331.61 | E4: =SUMIF(F8:F960,"DIST. PUBLICITAIRE SOLO",B8:B960) -> 0 | F4: =SUMIF(F8:F960,"AGENCE PUB",B8:B960) -> 0 | G4: =SUMIF(F8:F960,"AGENCE WEB",B8:B960) -> 0 | H4: =SUMIF(F8:F960,"SERVICES IA",B8:B960) -> 0
A7: CLIENT | B7: TOTAL(AVANTTAXES) | C7: # FACTURE | D7: DATE | E7: REPRÉSENTANT | F7: DÉPARTEMENT | G7: COMMISSION
A8: LaGermaineResto | B8: 49.04 | C8: QC-019906 | D8: 46112 | E8: MorganeOwczarzak | F8: PROMOTIONNEL | G8: =B8*0.1 -> 4.904
A9: LaGermaineResto | B9: 472.08 | C9: QC-019905 | D9: 46112 | E9: MorganeOwczarzak | F9: PROMOTIONNEL | G9: =B9*0.1 -> 47.208
A10: LaGermaineResto | B10: 356.61 | C10: QC-019904 | D10: 46112 | E10: MorganeOwczarzak | F10: PROMOTIONNEL | G10: =B10*0.1 -> 35.661
A11: SNEEKronosCanada | B11: 4930.74 | C11: QC-019903 | D11: 46112 | E11: MorganeOwczarzak | F11: PROMOTIONNEL | G11: =B11*0.1 -> 493.074
A12: LEMBRO | B12: 443.19 | C12: QC-019891 | D12: 46111 | E12: MorganeOwczarzak | F12: PROMOTIONNEL | G12: =B12*0.1 -> 44.319
A13: PlateformeBioalimentairesolidar | B13: 635 | C13: QC-019890 | D13: 46111 | E13: MorganeOwczarzak | F13: PROMOTIONNEL | G13: =B13*0.1 -> 63.5
A14: GrueMobileVeilleuxInc. | B14: 1690 | C14: QC-019889 | D14: 46111 | E14: MorganeOwczarzak | F14: PROMOTIONNEL | G14: =B14*0.1 -> 169
A15: LavagedevitresÉlite | B15: 1137.97 | C15: QC-019882 | D15: 46111 | E15: MorganeOwczarzak | F15: PROMOTIONNEL | G15: =B15*0.1 -> 113.797
A16: SPIQInspectionIncendie | B16: 147.3 | C16: QC-019840 | D16: 46106 | E16: MorganeOwczarzak | F16: PROMOTIONNEL | G16: =B16*0.1 -> 14.73
A17: Rénov-actionD.Rinc | B17: 494.5 | C17: QC-019834 | D17: 46106 | E17: MorganeOwczarzak | F17: PROMOTIONNEL | G17: =B17*0.1 -> 49.45
A18: Clubdel'âged'Or | B18: 257.5 | C18: QC-019833 | D18: 46106 | E18: MorganeOwczarzak | F18: PROMOTIONNEL | G18: =B18*0.1 -> 25.75
A19: CIUSSSduCentre-Sud-de-l'Île-de-Montréal | B19: 1437.78 | C19: QC-019791 | D19: 46101 | E19: MorganeOwczarzak | F19: PROMOTIONNEL | G19: =B19*0.1 -> 143.778
... A24: ClubdecanotageOBC | B24: 3035 | C24: QC-019531 | D24: 46083 | E24: MorganeOwczarzak | F24: PROMOTIONNEL | G24: =B24*0.1 -> 303.5
G25: =B25*0.1 -> 0
G26: =B26*0.1 -> 0
G27: =B27*0.1 -> 0
G28: =B28*0.1 -> 0
G29: =B29*0.1 -> 0
G30: =B30*0.1 -> 0
G31: =B31*0.1 -> 0
G32: =B32*0.1 -> 0
G33: =B33*0.1 -> 0
G34: =B34*0.1 -> 0
G35: =B35*0.1 -> 0
G36: =B36*0.1 -> 0
... G166: =B166*0.1 -> 0
G167: =B167*0.05 -> 0
G168: =B168*0.05 -> 0
G169: =B169*0.05 -> 0
G170: =B170*0.05 -> 0
G171: =B171*0.05 -> 0
G172: =B172*0.05 -> 0
G173: =B173*0.05 -> 0
G174: =B174*0.05 -> 0
G175: =B175*0.05 -> 0
G176: =B176*0.05 -> 0
...

Sheet Avril
B1: Totaux | C1: MÉDIA MULTI-ANNONCEURS | D1: PROMOTIONNEL | E1: DIST. PUBLICITAIRE SOLO | F1: NUMÉRIQUE | G1: APPLICATION | H1: SERVICES IA
A2: Commission | B2: =SUM(G7:G961) -> 3032.444 | C2: =SUMIF(F8:F959,"MÉDIA MULTI-ANNONCEURS",G8:G959) -> 0 | D2: =SUMIF(F8:F959,"PROMOTIONNEL",G8:G959) -> 3032.444 | E2: =SUMIF(F8:F959,"DIST. PUBLICITAIRE SOLO",G8:G959) -> 0 | F2: =SUMIF(F8:F959,"AGENCE PUB",G8:G959) -> 0 | G2: =SUMIF(F8:F959,"AGENCE WEB",G8:G959) -> 0 | H2: =SUMIF(F8:F959,"SERVICES IA",G8:G959) -> 0
A4: Vente | B4: =SUM(B8:B961) -> 30324.44 | C4: =SUMIF(F8:F959,"MÉDIA MULTI-ANNONCEURS",B8:B959) -> 0 | D4: =SUMIF(F8:F959,"PROMOTIONNEL",B8:B959) -> 30324.44 | E4: =SUMIF(F8:F959,"DIST. PUBLICITAIRE SOLO",B8:B959) -> 0 | F4: =SUMIF(F8:F959,"AGENCE PUB",B8:B959) -> 0 | G4: =SUMIF(F8:F959,"AGENCE WEB",B8:B959) -> 0 | H4: =SUMIF(F8:F959,"SERVICES IA",B8:B959) -> 0
A7: CLIENT | B7: TOTAL (AVANT TAXES) | C7: # FACTURE | D7: DATE | E7: REPRÉSENTANT | F7: DÉPARTEMENT | G7: COMMISSION
A8: Les Entreprises Roseneige | B8: 8765.85 | C8: QC-019986 | D8: 46113 | E8: Morgane Owczarzak | F8: PROMOTIONNEL | G8: =B8*0.1 -> 876.585
A9: LEMBRO | B9: 418.15 | C9: QC-020046 | D9: 46114 | E9: Morgane Owczarzak | F9: PROMOTIONNEL | G9: =B9*0.1 -> 41.815
A10: Maxxing | B10: 2465 | C10: QC-020053 | D10: 46118 | E10: Morgane Owczarzak | F10: PROMOTIONNEL | G10: =B10*0.1 -> 246.5
A11: CR PRO Solution Inc. | B11: 76 | C11: QC-020084 | D11: 46118 | E11: Morgane Owczarzak | F11: PROMOTIONNEL | G11: =B11*0.1 -> 7.6
A12: Daniel Paré | B12: 322.5 | C12: QC-020114 | D12: 46120 | E12: Morgane Owczarzak | F12: PROMOTIONNEL | G12: =B12*0.1 -> 32.25
A13: Services horticoles pouce-vert | B13: 2586.46 | C13: QC-020112 | D13: 46120 | E13: Morgane Owczarzak | F13: PROMOTIONNEL | G13: =B13*0.1 -> 258.646
A14: LEMBRO | B14: 90.8 | C14: QC-020109 | D14: 46120 | E14: Morgane Owczarzak | F14: PROMOTIONNEL | G14: =B14*0.1 -> 9.08
A15: Kaboom auto-tamponneuse Inc | B15: 375 | C15: QC-020134 | D15: 46121 | E15: Morgane Owczarzak | F15: PROMOTIONNEL | G15: =B15*0.1 -> 37.5
A16: Kaboom auto-tamponneuse Inc | B16: 1128.35 | C16: QC-020146 | D16: 46122 | E16: Morgane Owczarzak | F16: PROMOTIONNEL | G16: =B16*0.1 -> 112.835
A17: Costco Wholesale | B17: 222.54 | C17: QC-020143 | D17: 46122 | E17: Morgane Owczarzak | F17: PROMOTIONNEL | G17: =B17*0.1 -> 22.254
A18: Transport Mathieu Lessard | B18: 313.27 | C18: QC-020142 | D18: 46122 | E18: Morgane Owczarzak | F18: PROMOTIONNEL | G18: =B18*0.1 -> 31.327
A19: Kanatrac | B19: 60 | C19: QC-020140 | D19: 46122 | E19: Morgane Owczarzak | F19: PROMOTIONNEL | G19: =B19*0.1 -> 6
... A28: SNEE Kronos Canada | B28: -61.35 | C28: CN-01185 | D28: 46132 | E28: Morgane Owczarzak | F28: PROMOTIONNEL | G28: =B28*0.1 -> -6.135
G29: =B29*0.1 -> 0
G30: =B30*0.1 -> 0
G31: =B31*0.1 -> 0
G32: =B32*0.1 -> 0
G33: =B33*0.1 -> 0
G34: =B34*0.1 -> 0
G35: =B35*0.1 -> 0
G36: =B36*0.1 -> 0
G37: =B37*0.1 -> 0
G38: =B38*0.1 -> 0
G39: =B39*0.1 -> 0
G40: =B40*0.1 -> 0
... G165: =B165*0.1 -> 0
G166: =B166*0.05 -> 0
G167: =B167*0.05 -> 0
G168: =B168*0.05 -> 0
G169: =B169*0.05 -> 0
G170: =B170*0.05 -> 0
G171: =B171*0.05 -> 0
G172: =B172*0.05 -> 0
G173: =B173*0.05 -> 0
G174: =B174*0.05 -> 0
G175: =B175*0.05 -> 0
...

Sheet Mai
B1: Totaux | C1: MÉDIA MULTI-ANNONCEURS | D1: PROMOTIONNEL | E1: DIST. PUBLICITAIRE SOLO | F1: NUMÉRIQUE | G1: APPLICATION | H1: SERVICES IA
A2: Commission | B2: =SUM(G7:G962) -> 0 | C2: =SUMIF(F8:F960,"MÉDIA MULTI-ANNONCEURS",G8:G960) -> 0 | D2: =SUMIF(F8:F960,"PROMOTIONNEL",G8:G960) -> 0 | E2: =SUMIF(F8:F960,"DIST. PUBLICITAIRE SOLO",G8:G960) -> 0 | F2: =SUMIF(F8:F960,"AGENCE PUB",G8:G960) -> 0 | G2: =SUMIF(F8:F960,"AGENCE WEB",G8:G960) -> 0 | H2: =SUMIF(F8:F960,"SERVICES IA",G8:G960) -> 0
A4: Vente | B4: =SUM(B8:B962) -> 0 | C4: =SUMIF(F8:F960,"MÉDIA MULTI-ANNONCEURS",B8:B960) -> 0 | D4: =SUMIF(F8:F960,"PROMOTIONNEL",B8:B960) -> 0 | E4: =SUMIF(F8:F960,"DIST. PUBLICITAIRE SOLO",B8:B960) -> 0 | F4: =SUMIF(F8:F960,"AGENCE PUB",B8:B960) -> 0 | G4: =SUMIF(F8:F960,"AGENCE WEB",B8:B960) -> 0 | H4: =SUMIF(F8:F960,"SERVICES IA",B8:B960) -> 0
A7: CLIENT | B7: TOTAL (AVANT TAXES) | C7: # FACTURE | D7: DATE | E7: REPRÉSENTANT | F7: DÉPARTEMENT | G7: COMMISSION
G8: =B8*0.1 -> 0
G9: =B9*0.1 -> 0
G10: =B10*0.1 -> 0
G11: =B11*0.1 -> 0
G12: =B12*0.1 -> 0
G13: =B13*0.1 -> 0
G14: =B14*0.1 -> 0
G15: =B15*0.1 -> 0
G16: =B16*0.1 -> 0
G17: =B17*0.1 -> 0
G18: =B18*0.1 -> 0
G19: =B19*0.1 -> 0
... G166: =B166*0.1 -> 0
G167: =B167*0.05 -> 0
G168: =B168*0.05 -> 0
G169: =B169*0.05 -> 0
G170: =B170*0.05 -> 0
G171: =B171*0.05 -> 0
G172: =B172*0.05 -> 0
G173: =B173*0.05 -> 0
G174: =B174*0.05 -> 0
G175: =B175*0.05 -> 0
G176: =B176*0.05 -> 0
G177: =B177*0.05 -> 0
G178: =B178*0.05 -> 0
... G212: =B212*0.05 -> 0

Sheet Juin
B1: Totaux | C1: MÉDIA MULTI-ANNONCEURS | D1: PROMOTIONNEL | E1: DIST. PUBLICITAIRE SOLO | F1: NUMÉRIQUE | G1: APPLICATION | H1: SERVICES IA
A2: Commission | B2: =SUM(G7:G962) -> 0 | C2: =SUMIF(F8:F960,"MÉDIA MULTI-ANNONCEURS",G8:G960) -> 0 | D2: =SUMIF(F8:F960,"PROMOTIONNEL",G8:G960) -> 0 | E2: =SUMIF(F8:F960,"DIST. PUBLICITAIRE SOLO",G8:G960) -> 0 | F2: =SUMIF(F8:F960,"AGENCE PUB",G8:G960) -> 0 | G2: =SUMIF(F8:F960,"AGENCE WEB",G8:G960) -> 0 | H2: =SUMIF(F8:F960,"SERVICES IA",G8:G960) -> 0
A4: Vente | B4: =SUM(B8:B962) -> 0 | C4: =SUMIF(F8:F960,"MÉDIA MULTI-ANNONCEURS",B8:B960) -> 0 | D4: =SUMIF(F8:F960,"PROMOTIONNEL",B8:B960) -> 0 | E4: =SUMIF(F8:F960,"DIST. PUBLICITAIRE SOLO",B8:B960) -> 0 | F4: =SUMIF(F8:F960,"AGENCE PUB",B8:B960) -> 0 | G4: =SUMIF(F8:F960,"AGENCE WEB",B8:B960) -> 0 | H4: =SUMIF(F8:F960,"SERVICES IA",B8:B960) -> 0
A7: CLIENT | B7: TOTAL (AVANT TAXES) | C7: # FACTURE | D7: DATE | E7: REPRÉSENTANT | F7: DÉPARTEMENT | G7: COMMISSION
G8: =B8*0.1 -> 0
G9: =B9*0.1 -> 0
G10: =B10*0.1 -> 0
G11: =B11*0.1 -> 0
G12: =B12*0.1 -> 0
G13: =B13*0.1 -> 0
G14: =B14*0.1 -> 0
G15: =B15*0.1 -> 0
G16: =B16*0.1 -> 0
G17: =B17*0.1 -> 0
G18: =B18*0.1 -> 0
G19: =B19*0.1 -> 0
... G166: =B166*0.1 -> 0
G167: =B167*0.05 -> 0
G168: =B168*0.05 -> 0
G169: =B169*0.05 -> 0
G170: =B170*0.05 -> 0
G171: =B171*0.05 -> 0
G172: =B172*0.05 -> 0
G173: =B173*0.05 -> 0
G174: =B174*0.05 -> 0
G175: =B175*0.05 -> 0
G176: =B176*0.05 -> 0
G177: =B177*0.05 -> 0
G178: =B178*0.05 -> 0
... G212: =B212*0.05 -> 0

Sheet Juillet
B1: Totaux | C1: MÉDIA MULTI-ANNONCEURS | D1: PROMOTIONNEL | E1: DIST. PUBLICITAIRE SOLO | F1: NUMÉRIQUE | G1: APPLICATION | H1: SERVICES IA
A2: Commission | B2: =SUM(G7:G962) -> 0 | C2: =SUMIF(F8:F960,"MÉDIA MULTI-ANNONCEURS",G8:G960) -> 0 | D2: =SUMIF(F8:F960,"PROMOTIONNEL",G8:G960) -> 0 | E2: =SUMIF(F8:F960,"DIST. PUBLICITAIRE SOLO",G8:G960) -> 0 | F2: =SUMIF(F8:F960,"AGENCE PUB",G8:G960) -> 0 | G2: =SUMIF(F8:F960,"AGENCE WEB",G8:G960) -> 0 | H2: =SUMIF(F8:F960,"SERVICES IA",G8:G960) -> 0
A4: Vente | B4: =SUM(B8:B962) -> 0 | C4: =SUMIF(F8:F960,"MÉDIA MULTI-ANNONCEURS",B8:B960) -> 0 | D4: =SUMIF(F8:F960,"PROMOTIONNEL",B8:B960) -> 0 | E4: =SUMIF(F8:F960,"DIST. PUBLICITAIRE SOLO",B8:B960) -> 0 | F4: =SUMIF(F8:F960,"AGENCE PUB",B8:B960) -> 0 | G4: =SUMIF(F8:F960,"AGENCE WEB",B8:B960) -> 0 | H4: =SUMIF(F8:F960,"SERVICES IA",B8:B960) -> 0
A7: CLIENT | B7: TOTAL (AVANT TAXES) | C7: # FACTURE | D7: DATE | E7: REPRÉSENTANT | F7: DÉPARTEMENT | G7: COMMISSION
G8: =B8*0.1 -> 0
G9: =B9*0.1 -> 0
G10: =B10*0.1 -> 0
G11: =B11*0.1 -> 0
G12: =B12*0.1 -> 0
G13: =B13*0.1 -> 0
G14: =B14*0.1 -> 0
G15: =B15*0.1 -> 0
G16: =B16*0.1 -> 0
G17: =B17*0.1 -> 0
G18: =B18*0.1 -> 0
G19: =B19*0.1 -> 0
... G166: =B166*0.1 -> 0
G167: =B167*0.05 -> 0
G168: =B168*0.05 -> 0
G169: =B169*0.05 -> 0
G170: =B170*0.05 -> 0
G171: =B171*0.05 -> 0
G172: =B172*0.05 -> 0
G173: =B173*0.05 -> 0
G174: =B174*0.05 -> 0
G175: =B175*0.05 -> 0
G176: =B176*0.05 -> 0
G177: =B177*0.05 -> 0
G178: =B178*0.05 -> 0
... G212: =B212*0.05 -> 0

Sheet Août
B1: Totaux | C1: MÉDIA MULTI-ANNONCEURS | D1: PROMOTIONNEL | E1: DIST. PUBLICITAIRE SOLO | F1: NUMÉRIQUE | G1: APPLICATION | H1: SERVICES IA
A2: Commission | B2: =SUM(G7:G962) -> 0 | C2: =SUMIF(F8:F960,"MÉDIA MULTI-ANNONCEURS",G8:G960) -> 0 | D2: =SUMIF(F8:F960,"PROMOTIONNEL",G8:G960) -> 0 | E2: =SUMIF(F8:F960,"DIST. PUBLICITAIRE SOLO",G8:G960) -> 0 | F2: =SUMIF(F8:F960,"AGENCE PUB",G8:G960) -> 0 | G2: =SUMIF(F8:F960,"AGENCE WEB",G8:G960) -> 0 | H2: =SUMIF(F8:F960,"SERVICES IA",G8:G960) -> 0
A4: Vente | B4: =SUM(B8:B962) -> 0 | C4: =SUMIF(F8:F960,"MÉDIA MULTI-ANNONCEURS",B8:B960) -> 0 | D4: =SUMIF(F8:F960,"PROMOTIONNEL",B8:B960) -> 0 | E4: =SUMIF(F8:F960,"DIST. PUBLICITAIRE SOLO",B8:B960) -> 0 | F4: =SUMIF(F8:F960,"AGENCE PUB",B8:B960) -> 0 | G4: =SUMIF(F8:F960,"AGENCE WEB",B8:B960) -> 0 | H4: =SUMIF(F8:F960,"SERVICES IA",B8:B960) -> 0
A7: CLIENT | B7: TOTAL (AVANT TAXES) | C7: # FACTURE | D7: DATE | E7: REPRÉSENTANT | F7: DÉPARTEMENT | G7: COMMISSION
G8: =B8*0.1 -> 0
G9: =B9*0.1 -> 0
G10: =B10*0.1 -> 0
G11: =B11*0.1 -> 0
G12: =B12*0.1 -> 0
G13: =B13*0.1 -> 0
G14: =B14*0.1 -> 0
G15: =B15*0.1 -> 0
G16: =B16*0.1 -> 0
G17: =B17*0.1 -> 0
G18: =B18*0.1 -> 0
G19: =B19*0.1 -> 0
... G166: =B166*0.1 -> 0
G167: =B167*0.05 -> 0
G168: =B168*0.05 -> 0
G169: =B169*0.05 -> 0
G170: =B170*0.05 -> 0
G171: =B171*0.05 -> 0
G172: =B172*0.05 -> 0
G173: =B173*0.05 -> 0
G174: =B174*0.05 -> 0
G175: =B175*0.05 -> 0
G176: =B176*0.05 -> 0
G177: =B177*0.05 -> 0
G178: =B178*0.05 -> 0
... G212: =B212*0.05 -> 0

Sheet Septembre
B1: Totaux | C1: MÉDIA MULTI-ANNONCEURS | D1: PROMOTIONNEL | E1: DIST. PUBLICITAIRE SOLO | F1: NUMÉRIQUE | G1: APPLICATION | H1: SERVICES IA
A2: Commission | B2: =SUM(G7:G962) -> 0 | C2: =SUMIF(F8:F960,"MÉDIA MULTI-ANNONCEURS",G8:G960) -> 0 | D2: =SUMIF(F8:F960,"PROMOTIONNEL",G8:G960) -> 0 | E2: =SUMIF(F8:F960,"DIST. PUBLICITAIRE SOLO",G8:G960) -> 0 | F2: =SUMIF(F8:F960,"AGENCE PUB",G8:G960) -> 0 | G2: =SUMIF(F8:F960,"AGENCE WEB",G8:G960) -> 0 | H2: =SUMIF(F8:F960,"SERVICES IA",G8:G960) -> 0
A4: Vente | B4: =SUM(B8:B962) -> 0 | C4: =SUMIF(F8:F960,"MÉDIA MULTI-ANNONCEURS",B8:B960) -> 0 | D4: =SUMIF(F8:F960,"PROMOTIONNEL",B8:B960) -> 0 | E4: =SUMIF(F8:F960,"DIST. PUBLICITAIRE SOLO",B8:B960) -> 0 | F4: =SUMIF(F8:F960,"AGENCE PUB",B8:B960) -> 0 | G4: =SUMIF(F8:F960,"AGENCE WEB",B8:B960) -> 0 | H4: =SUMIF(F8:F960,"SERVICES IA",B8:B960) -> 0
A7: CLIENT | B7: TOTAL (AVANT TAXES) | C7: # FACTURE | D7: DATE | E7: REPRÉSENTANT | F7: DÉPARTEMENT | G7: COMMISSION
G8: =B8*0.1 -> 0
G9: =B9*0.1 -> 0
G10: =B10*0.1 -> 0
G11: =B11*0.1 -> 0
G12: =B12*0.1 -> 0
G13: =B13*0.1 -> 0
G14: =B14*0.1 -> 0
G15: =B15*0.1 -> 0
G16: =B16*0.1 -> 0
G17: =B17*0.1 -> 0
G18: =B18*0.1 -> 0
G19: =B19*0.1 -> 0
... G166: =B166*0.1 -> 0
G167: =B167*0.05 -> 0
G168: =B168*0.05 -> 0
G169: =B169*0.05 -> 0
G170: =B170*0.05 -> 0
G171: =B171*0.05 -> 0
G172: =B172*0.05 -> 0
G173: =B173*0.05 -> 0
G174: =B174*0.05 -> 0
G175: =B175*0.05 -> 0
G176: =B176*0.05 -> 0
G177: =B177*0.05 -> 0
G178: =B178*0.05 -> 0
... G212: =B212*0.05 -> 0

Sheet Octobre
B1: Totaux | C1: MÉDIA MULTI-ANNONCEURS | D1: PROMOTIONNEL | E1: DIST. PUBLICITAIRE SOLO | F1: NUMÉRIQUE | G1: APPLICATION | H1: SERVICES IA
A2: Commission | B2: =SUM(G7:G962) -> 0 | C2: =SUMIF(F8:F960,"MÉDIA MULTI-ANNONCEURS",G8:G960) -> 0 | D2: =SUMIF(F8:F960,"PROMOTIONNEL",G8:G960) -> 0 | E2: =SUMIF(F8:F960,"DIST. PUBLICITAIRE SOLO",G8:G960) -> 0 | F2: =SUMIF(F8:F960,"AGENCE PUB",G8:G960) -> 0 | G2: =SUMIF(F8:F960,"AGENCE WEB",G8:G960) -> 0 | H2: =SUMIF(F8:F960,"SERVICES IA",G8:G960) -> 0
A4: Vente | B4: =SUM(B8:B962) -> 0 | C4: =SUMIF(F8:F960,"MÉDIA MULTI-ANNONCEURS",B8:B960) -> 0 | D4: =SUMIF(F8:F960,"PROMOTIONNEL",B8:B960) -> 0 | E4: =SUMIF(F8:F960,"DIST. PUBLICITAIRE SOLO",B8:B960) -> 0 | F4: =SUMIF(F8:F960,"AGENCE PUB",B8:B960) -> 0 | G4: =SUMIF(F8:F960,"AGENCE WEB",B8:B960) -> 0 | H4: =SUMIF(F8:F960,"SERVICES IA",B8:B960) -> 0
A7: CLIENT | B7: TOTAL (AVANT TAXES) | C7: # FACTURE | D7: DATE | E7: REPRÉSENTANT | F7: DÉPARTEMENT | G7: COMMISSION
G8: =B8*0.1 -> 0
G9: =B9*0.1 -> 0
G10: =B10*0.1 -> 0
G11: =B11*0.1 -> 0
G12: =B12*0.1 -> 0
G13: =B13*0.1 -> 0
G14: =B14*0.1 -> 0
G15: =B15*0.1 -> 0
G16: =B16*0.1 -> 0
G17: =B17*0.1 -> 0
G18: =B18*0.1 -> 0
G19: =B19*0.1 -> 0
... G166: =B166*0.1 -> 0
G167: =B167*0.05 -> 0
G168: =B168*0.05 -> 0
G169: =B169*0.05 -> 0
G170: =B170*0.05 -> 0
G171: =B171*0.05 -> 0
G172: =B172*0.05 -> 0
G173: =B173*0.05 -> 0
G174: =B174*0.05 -> 0
G175: =B175*0.05 -> 0
G176: =B176*0.05 -> 0
G177: =B177*0.05 -> 0
G178: =B178*0.05 -> 0
... G212: =B212*0.05 -> 0

Sheet Novembre
B1: Totaux | C1: MÉDIA MULTI-ANNONCEURS | D1: PROMOTIONNEL | E1: DIST. PUBLICITAIRE SOLO | F1: NUMÉRIQUE | G1: APPLICATION | H1: SERVICES IA
A2: Commission | B2: =SUM(G7:G962) -> 0 | C2: =SUMIF(F8:F960,"MÉDIA MULTI-ANNONCEURS",G8:G960) -> 0 | D2: =SUMIF(F8:F960,"PROMOTIONNEL",G8:G960) -> 0 | E2: =SUMIF(F8:F960,"DIST. PUBLICITAIRE SOLO",G8:G960) -> 0 | F2: =SUMIF(F8:F960,"AGENCE PUB",G8:G960) -> 0 | G2: =SUMIF(F8:F960,"AGENCE WEB",G8:G960) -> 0 | H2: =SUMIF(F8:F960,"SERVICES IA",G8:G960) -> 0
A4: Vente | B4: =SUM(B8:B962) -> 0 | C4: =SUMIF(F8:F960,"MÉDIA MULTI-ANNONCEURS",B8:B960) -> 0 | D4: =SUMIF(F8:F960,"PROMOTIONNEL",B8:B960) -> 0 | E4: =SUMIF(F8:F960,"DIST. PUBLICITAIRE SOLO",B8:B960) -> 0 | F4: =SUMIF(F8:F960,"AGENCE PUB",B8:B960) -> 0 | G4: =SUMIF(F8:F960,"AGENCE WEB",B8:B960) -> 0 | H4: =SUMIF(F8:F960,"SERVICES IA",B8:B960) -> 0
A7: CLIENT | B7: TOTAL (AVANT TAXES) | C7: # FACTURE | D7: DATE | E7: REPRÉSENTANT | F7: DÉPARTEMENT | G7: COMMISSION
G8: =B8*0.1 -> 0
G9: =B9*0.1 -> 0
G10: =B10*0.1 -> 0
G11: =B11*0.1 -> 0
G12: =B12*0.1 -> 0
G13: =B13*0.1 -> 0
G14: =B14*0.1 -> 0
G15: =B15*0.1 -> 0
G16: =B16*0.1 -> 0
G17: =B17*0.1 -> 0
G18: =B18*0.1 -> 0
G19: =B19*0.1 -> 0
... G166: =B166*0.1 -> 0
G167: =B167*0.05 -> 0
G168: =B168*0.05 -> 0
G169: =B169*0.05 -> 0
G170: =B170*0.05 -> 0
G171: =B171*0.05 -> 0
G172: =B172*0.05 -> 0
G173: =B173*0.05 -> 0
G174: =B174*0.05 -> 0
G175: =B175*0.05 -> 0
G176: =B176*0.05 -> 0
G177: =B177*0.05 -> 0
G178: =B178*0.05 -> 0
... G212: =B212*0.05 -> 0

Sheet Décembre
B1: Totaux | C1: MÉDIA MULTI-ANNONCEURS | D1: PROMOTIONNEL | E1: DIST. PUBLICITAIRE SOLO | F1: NUMÉRIQUE | G1: APPLICATION | H1: SERVICES IA
A2: Commission | B2: =SUM(G7:G962) -> 0 | C2: =SUMIF(F8:F960,"MÉDIA MULTI-ANNONCEURS",G8:G960) -> 0 | D2: =SUMIF(F8:F960,"PROMOTIONNEL",G8:G960) -> 0 | E2: =SUMIF(F8:F960,"DIST. PUBLICITAIRE SOLO",G8:G960) -> 0 | F2: =SUMIF(F8:F960,"AGENCE PUB",G8:G960) -> 0 | G2: =SUMIF(F8:F960,"AGENCE WEB",G8:G960) -> 0 | H2: =SUMIF(F8:F960,"SERVICES IA",G8:G960) -> 0
A4: Vente | B4: =SUM(B8:B962) -> 0 | C4: =SUMIF(F8:F960,"MÉDIA MULTI-ANNONCEURS",B8:B960) -> 0 | D4: =SUMIF(F8:F960,"PROMOTIONNEL",B8:B960) -> 0 | E4: =SUMIF(F8:F960,"DIST. PUBLICITAIRE SOLO",B8:B960) -> 0 | F4: =SUMIF(F8:F960,"AGENCE PUB",B8:B960) -> 0 | G4: =SUMIF(F8:F960,"AGENCE WEB",B8:B960) -> 0 | H4: =SUMIF(F8:F960,"SERVICES IA",B8:B960) -> 0
A7: CLIENT | B7: TOTAL (AVANT TAXES) | C7: # FACTURE | D7: DATE | E7: REPRÉSENTANT | F7: DÉPARTEMENT | G7: COMMISSION
G8: =B8*0.1 -> 0
G9: =B9*0.1 -> 0
G10: =B10*0.1 -> 0
G11: =B11*0.1 -> 0
G12: =B12*0.1 -> 0
G13: =B13*0.1 -> 0
G14: =B14*0.1 -> 0
G15: =B15*0.1 -> 0
G16: =B16*0.1 -> 0
G17: =B17*0.1 -> 0
G18: =B18*0.1 -> 0
G19: =B19*0.1 -> 0
... G166: =B166*0.1 -> 0
G167: =B167*0.05 -> 0
G168: =B168*0.05 -> 0
G169: =B169*0.05 -> 0
G170: =B170*0.05 -> 0
G171: =B171*0.05 -> 0
G172: =B172*0.05 -> 0
G173: =B173*0.05 -> 0
G174: =B174*0.05 -> 0
G175: =B175*0.05 -> 0
G176: =B176*0.05 -> 0
G177: =B177*0.05 -> 0
G178: =B178*0.05 -> 0
... G212: =B212*0.05 -> 0
