Workbook

Sheet Objectif
A1: OBJECTIF ANNUEL
C2: Total
A3: Période | C3: 2025 | D3: 2026 | F3: Objectif | G3: % atteint | K3: Vente de l'année | L3: =D16 -> 473587.72
A4: JANVIER | C4: =C21+G21+K21+O21+S21+W21 -> 46995.62 | D4: =Janvier!B4 -> 71910.34 | F4: =E21+I21+M21+Q21+U21+Y21 -> 66000 | G4: =D4/F4 -> 1.0895506
A5: FÉVRIER | C5: =C22+G22+K22+O22+S22+W22 -> 97596.8 | D5: ='Février'!B4 -> 133750.99 | F5: =E22+I22+M22+Q22+U22+Y22 -> 113000 | G5: =D5/F5 -> 1.1836371 | K5: Objectif de vente annuel | L5: =E33+I33+M33+Q33+U33+Y33 -> 1450000
A6: MARS | C6: =C23+G23+K23+O23+S23+W23 -> 134397.27 | D6: =Mars!B4 -> 154899.78 | F6: =E23+I23+M23+Q23+U23+Y23 -> 151600 | G6: =D6/F6 -> 1.0217664
A7: AVRIL | C7: =C24+G24+K24+O24+S24+W24 -> 157307.3 | D7: =Avril!B4 -> 113026.61 | F7: =E24+I24+M24+Q24+U24+Y24 -> 166600 | G7: =D7/F7 -> 0.67843103 | K7: % atteint | L7: =L3/L5 -> 0.32661222
A8: MAI | C8: =C25+G25+K25+O25+S25+W25 -> 134565.28 | D8: =Mai!B4 -> 0 | F8: =E25+I25+M25+Q25+U25+Y25 -> 151600 | G8: =D8/F8 -> 0
A9: JUIN | C9: =C26+G26+K26+O26+S26+W26 -> 85404.73 | D9: =Juin!B4 -> 0 | F9: =E26+I26+M26+Q26+U26+Y26 -> 106600 | G9: =D9/F9 -> 0
A10: JUILLET | C10: =C27+G27+K27+O27+S27+W27 -> 156058.4 | D10: =Juillet!B4 -> 0 | F10: =E27+I27+M27+Q27+U27+Y27 -> 116600 | G10: =D10/F10 -> 0
A11: AOÛT | C11: =C28+G28+K28+O28+S28+W28 -> 90266.76 | D11: ='Août'!B4 -> 0 | F11: =E28+I28+M28+Q28+U28+Y28 -> 106600 | G11: =D11/F11 -> 0
A12: SEPTEMBRE | C12: =C29+G29+K29+O29+S29+W29 -> 118995.46 | D12: =Septembre!B4 -> 0 | F12: =E29+I29+M29+Q29+U29+Y29 -> 141600 | G12: =D12/F12 -> 0
A13: OCTOBRE | C13: =C30+G30+K30+O30+S30+W30 -> 430214.33 | D13: =Octobre!B4 -> 0 | F13: =E30+I30+M30+Q30+U30+Y30 -> 146600 | G13: =D13/F13 -> 0
A14: NOVEMBRE | C14: =C31+G31+K31+O31+S31+W31 -> 115639.1 | D14: =Novembre!B4 -> 0 | F14: =E31+I31+M31+Q31+U31+Y31 -> 110600 | G14: =D14/F14 -> 0
A15: DÉCEMBRE | C15: =C32+G32+K32+O32+S32+W32 -> 69384.19 | D15: ='Décembre'!B4 -> 0 | F15: =E32+I32+M32+Q32+U32+Y32 -> 72600 | G15: =D15/F15 -> 0
A16: Total | C16: =SUM(C4:C15) -> 1636825.2 | D16: =SUM(D4:D15) -> 473587.72 | F16: =SUM(F4:F15) -> 1450000 | G16: =D16/F16 -> 0.32661222
C19: MULTI-ANNONCEURS | G19: PROMOTIONNEL | K19: DIST. PUBLICITAIRE SOLO | O19: NUMÉRIQUE | S19: APPLICATION | W19: SERVICES IA
A20: Période | C20: 2025 | D20: 2026 | E20: Objectif | F20: % atteint | G20: 2025 | H20: 2026 | I20: Objectif | J20: % atteint | K20: 2025 | L20: 2026 | M20: Objectif | N20: % atteint | O20: 2025 | P20: 2026 | Q20: Objectif | R20: % atteint | S20: 2025 | T20: 2026 | U20: Objectif | V20: % atteint | W20: 2025 | X20: 2026 | Y20: Objectif | Z20: % atteint
A21: JANVIER | C21: =IFERROR(__xludf.DUMMYFUNCTION("IMPORTRANGE(""https://docs.google.com/spreadsheets/d/1-ltm482s1dBBbw9MUTGac60xYPDomqoML6LZHNmZNIM/edit?gid=2000300900#gid=2000300900"",""OBJECTIF!D21:D32"")"),5345.0) -> 5345 | D21: =Janvier!C4 -> 5785 | E21: 6000 | F21: =D21/E21 -> 0.96416667 | G21: =IFERROR(__xludf.DUMMYFUNCTION("IMPORTRANGE(""https://docs.google.com/spreadsheets/d/1-ltm482s1dBBbw9MUTGac60xYPDomqoML6LZHNmZNIM/edit?gid=2000300900#gid=2000300900"",""OBJECTIF!H21:H32"")"),25899.37) -> 25899.37 | H21: =Janvier!D4 -> 14677.91 | I21: 30000 | J21: =H21/I21 -> 0.48926367 | K21: =IFERROR(__xludf.DUMMYFUNCTION("IMPORTRANGE(""https://docs.google.com/spreadsheets/d/1-ltm482s1dBBbw9MUTGac60xYPDomqoML6LZHNmZNIM/edit?gid=2000300900#gid=2000300900"",""OBJECTIF!L21:L32"")"),493.75) -> 493.75 | L21: =Janvier!E4 -> 12183.18 | M21: 5000 | N21: =L21/M21 -> 2.436636 | O21: =IFERROR(__xludf.DUMMYFUNCTION("IMPORTRANGE(""https://docs.google.com/spreadsheets/d/1-ltm482s1dBBbw9MUTGac60xYPDomqoML6LZHNmZNIM/edit?gid=2000300900#gid=2000300900"",""OBJECTIF!P21:P32"")"),15257.5) -> 15257.5 | P21: =Janvier!F4 -> 38814.25 | Q21: 25000 | R21: =P21/Q21 -> 1.55257 | S21: =IFERROR(__xludf.DUMMYFUNCTION("IMPORTRANGE(""https://docs.google.com/spreadsheets/d/1-ltm482s1dBBbw9MUTGac60xYPDomqoML6LZHNmZNIM/edit?gid=2000300900#gid=2000300900"",""OBJECTIF!T21:T32"")"),0.0) -> 0 | T21: =Janvier!G4 -> 450 | V21: =T21/U21 -> #DIV/0! | X21: =Janvier!K4 | Y21: 0 | Z21: =X21/Y21 -> #DIV/0!
A22: FÉVRIER | C22: =IFERROR(__xludf.DUMMYFUNCTION("""COMPUTED_VALUE"""),4945.0) -> 4945 | D22: ='Février'!C4 -> 3585 | E22: 6000 | F22: =D22/E22 -> 0.5975 | G22: =IFERROR(__xludf.DUMMYFUNCTION("""COMPUTED_VALUE"""),64439.36000000001) -> 64439.36 | H22: ='Février'!D4 -> 38970.1 | I22: 70000 | J22: =H22/I22 -> 0.55671571 | K22: =IFERROR(__xludf.DUMMYFUNCTION("""COMPUTED_VALUE"""),5383.76) -> 5383.76 | L22: ='Février'!E4 -> 65370.64 | M22: 12000 | N22: =L22/M22 -> 5.4475533 | O22: =IFERROR(__xludf.DUMMYFUNCTION("""COMPUTED_VALUE"""),22828.68) -> 22828.68 | P22: ='Février'!F4 -> 25825.25 | Q22: 25000 | R22: =P22/Q22 -> 1.03301 | S22: =IFERROR(__xludf.DUMMYFUNCTION("""COMPUTED_VALUE"""),0.0) -> 0 | T22: ='Février'!G4 -> 0 | V22: =T22/U22 -> #DIV/0! | X22: ='Février'!K4 | Y22: 0 | Z22: =X22/Y22 -> #DIV/0!
A23: MARS | C23: =IFERROR(__xludf.DUMMYFUNCTION("""COMPUTED_VALUE"""),34150.5) -> 34150.5 | D23: =Mars!C4 -> 21070 | E23: 30000 | F23: =D23/E23 -> 0.70233333 | G23: =IFERROR(__xludf.DUMMYFUNCTION("""COMPUTED_VALUE"""),66509.34999999999) -> 66509.35 | H23: =Mars!D4 -> 68962.68 | I23: 70000 | J23: =H23/I23 -> 0.98518114 | K23: =IFERROR(__xludf.DUMMYFUNCTION("""COMPUTED_VALUE"""),11642.61) -> 11642.61 | L23: =Mars!E4 -> 31386.85 | M23: 15000 | N23: =L23/M23 -> 2.0924567 | O23: =IFERROR(__xludf.DUMMYFUNCTION("""COMPUTED_VALUE"""),22094.81) -> 22094.81 | P23: =Mars!F4 -> 33480.25 | Q23: 25000 | R23: =P23/Q23 -> 1.33921 | S23: =IFERROR(__xludf.DUMMYFUNCTION("""COMPUTED_VALUE"""),0.0) -> 0 | T23: =Mars!G4 -> 0 | V23: =T23/U23 -> #DIV/0! | X23: =Mars!K4 | Y23: 11600 | Z23: =X23/Y23 -> 0
A24: AVRIL | C24: =IFERROR(__xludf.DUMMYFUNCTION("""COMPUTED_VALUE"""),33500.5) -> 33500.5 | D24: =Avril!C4 -> 25260 | E24: 30000 | F24: =D24/E24 -> 0.842 | G24: =IFERROR(__xludf.DUMMYFUNCTION("""COMPUTED_VALUE"""),79186.02000000002) -> 79186.02 | H24: =Avril!D4 -> 39064.61 | I24: 85000 | J24: =H24/I24 -> 0.45958365 | K24: =IFERROR(__xludf.DUMMYFUNCTION("""COMPUTED_VALUE"""),23780.53) -> 23780.53 | L24: =Avril!E4 -> 29332 | M24: 25000 | N24: =L24/M24 -> 1.17328 | O24: =IFERROR(__xludf.DUMMYFUNCTION("""COMPUTED_VALUE"""),20840.25) -> 20840.25 | P24: =Avril!F4 -> 6875 | Q24: 25000 | R24: =P24/Q24 -> 0.275 | S24: =IFERROR(__xludf.DUMMYFUNCTION("""COMPUTED_VALUE"""),0.0) -> 0 | T24: =Avril!G4 -> 0 | V24: =T24/U24 -> #DIV/0! | X24: =Avril!K4 | Y24: 1600 | Z24: =X24/Y24 -> 0
A25: MAI | C25: =IFERROR(__xludf.DUMMYFUNCTION("""COMPUTED_VALUE"""),14590.5) -> 14590.5 | D25: =Mai!C4 -> 0 | E25: 20000 | F25: =D25/E25 -> 0 | G25: =IFERROR(__xludf.DUMMYFUNCTION("""COMPUTED_VALUE"""),69990.17000000001) -> 69990.17 | H25: =Mai!D4 -> 0 | I25: 75000 | J25: =H25/I25 -> 0 | K25: =IFERROR(__xludf.DUMMYFUNCTION("""COMPUTED_VALUE"""),31045.86) -> 31045.86 | L25: =Mai!E4 -> 0 | M25: 30000 | N25: =L25/M25 -> 0 | O25: =IFERROR(__xludf.DUMMYFUNCTION("""COMPUTED_VALUE"""),18938.75) -> 18938.75 | P25: =Mai!F4 -> 0 | Q25: 25000 | R25: =P25/Q25 -> 0 | S25: =IFERROR(__xludf.DUMMYFUNCTION("""COMPUTED_VALUE"""),0.0) -> 0 | T25: =Mai!G4 -> 0 | V25: =T25/U25 -> #DIV/0! | X25: =Mai!K4 | Y25: 1600 | Z25: =X25/Y25 -> 0
A26: JUIN | C26: =IFERROR(__xludf.DUMMYFUNCTION("""COMPUTED_VALUE"""),17260.5) -> 17260.5 | D26: =Juin!C4 -> 0 | E26: 20000 | F26: =D26/E26 -> 0 | G26: =IFERROR(__xludf.DUMMYFUNCTION("""COMPUTED_VALUE"""),36756.18000000001) -> 36756.18 | H26: =Juin!D4 -> 0 | I26: 40000 | J26: =H26/I26 -> 0 | K26: =IFERROR(__xludf.DUMMYFUNCTION("""COMPUTED_VALUE"""),13619.900000000001) -> 13619.9 | L26: =Juin!E4 -> 0 | M26: 20000 | N26: =L26/M26 -> 0 | O26: =IFERROR(__xludf.DUMMYFUNCTION("""COMPUTED_VALUE"""),17768.15) -> 17768.15 | P26: =Juin!F4 -> 0 | Q26: 25000 | R26: =P26/Q26 -> 0 | S26: =IFERROR(__xludf.DUMMYFUNCTION("""COMPUTED_VALUE"""),0.0) -> 0 | T26: =Juin!G4 -> 0 | V26: =T26/U26 -> #DIV/0! | X26: =Juin!K4 | Y26: 1600 | Z26: =X26/Y26 -> 0
A27: JUILLET | C27: =IFERROR(__xludf.DUMMYFUNCTION("""COMPUTED_VALUE"""),12655.0) -> 12655 | D27: =Juillet!C4 -> 0 | E27: 15000 | F27: =D27/E27 -> 0 | G27: =IFERROR(__xludf.DUMMYFUNCTION("""COMPUTED_VALUE"""),47598.05) -> 47598.05 | H27: =Juillet!D4 -> 0 | I27: 50000 | J27: =H27/I27 -> 0 | K27: =IFERROR(__xludf.DUMMYFUNCTION("""COMPUTED_VALUE"""),80780.1) -> 80780.1 | L27: =Juillet!E4 -> 0 | M27: 25000 | N27: =L27/M27 -> 0 | O27: =IFERROR(__xludf.DUMMYFUNCTION("""COMPUTED_VALUE"""),14275.25) -> 14275.25 | P27: =Juillet!F4 -> 0 | Q27: 25000 | R27: =P27/Q27 -> 0 | S27: =IFERROR(__xludf.DUMMYFUNCTION("""COMPUTED_VALUE"""),750.0) -> 750 | T27: =Juillet!G4 -> 0 | V27: =T27/U27 -> #DIV/0! | X27: =Juillet!K4 | Y27: 1600 | Z27: =X27/Y27 -> 0
A28: AOÛT | C28: =IFERROR(__xludf.DUMMYFUNCTION("""COMPUTED_VALUE"""),21765.0) -> 21765 | D28: ='Août'!C4 -> 0 | E28: 20000 | F28: =D28/E28 -> 0 | G28: =IFERROR(__xludf.DUMMYFUNCTION("""COMPUTED_VALUE"""),47689.21) -> 47689.21 | H28: ='Août'!D4 -> 0 | I28: 50000 | J28: =H28/I28 -> 0 | K28: =IFERROR(__xludf.DUMMYFUNCTION("""COMPUTED_VALUE"""),1833.0) -> 1833 | L28: ='Août'!E4 -> 0 | M28: 10000 | N28: =L28/M28 -> 0 | O28: =IFERROR(__xludf.DUMMYFUNCTION("""COMPUTED_VALUE"""),18979.55) -> 18979.55 | P28: ='Août'!F4 -> 0 | Q28: 25000 | R28: =P28/Q28 -> 0 | S28: =IFERROR(__xludf.DUMMYFUNCTION("""COMPUTED_VALUE"""),0.0) -> 0 | T28: ='Août'!G4 -> 0 | V28: =T28/U28 -> #DIV/0! | X28: ='Août'!K4 | Y28: 1600 | Z28: =X28/Y28 -> 0
A29: SEPTEMBRE | C29: =IFERROR(__xludf.DUMMYFUNCTION("""COMPUTED_VALUE"""),5780.0) -> 5780 | D29: =Septembre!C4 -> 0 | E29: 10000 | F29: =D29/E29 -> 0 | G29: =IFERROR(__xludf.DUMMYFUNCTION("""COMPUTED_VALUE"""),64565.69) -> 64565.69 | H29: =Septembre!D4 -> 0 | I29: 70000 | J29: =H29/I29 -> 0 | K29: =IFERROR(__xludf.DUMMYFUNCTION("""COMPUTED_VALUE"""),33475.82) -> 33475.82 | L29: =Septembre!E4 -> 0 | M29: 35000 | N29: =L29/M29 -> 0 | O29: =IFERROR(__xludf.DUMMYFUNCTION("""COMPUTED_VALUE"""),15173.95) -> 15173.95 | P29: =Septembre!F4 -> 0 | Q29: 25000 | R29: =P29/Q29 -> 0 | S29: =IFERROR(__xludf.DUMMYFUNCTION("""COMPUTED_VALUE"""),0.0) -> 0 | T29: =Septembre!G4 -> 0 | V29: =T29/U29 -> #DIV/0! | X29: =Septembre!K4 | Y29: 1600 | Z29: =X29/Y29 -> 0
A30: OCTOBRE | C30: =IFERROR(__xludf.DUMMYFUNCTION("""COMPUTED_VALUE"""),-945.0) -> -945 | D30: =Octobre!C4 -> 0 | E30: 10000 | F30: =D30/E30 -> 0 | G30: =IFERROR(__xludf.DUMMYFUNCTION("""COMPUTED_VALUE"""),80809.22000000002) -> 80809.22 | H30: =Octobre!D4 -> 0 | I30: 80000 | J30: =H30/I30 -> 0 | K30: =IFERROR(__xludf.DUMMYFUNCTION("""COMPUTED_VALUE"""),327818.61) -> 327818.61 | L30: =Octobre!E4 -> 0 | M30: 30000 | N30: =L30/M30 -> 0 | O30: =IFERROR(__xludf.DUMMYFUNCTION("""COMPUTED_VALUE"""),22531.5) -> 22531.5 | P30: =Octobre!F4 -> 0 | Q30: 25000 | R30: =P30/Q30 -> 0 | S30: =IFERROR(__xludf.DUMMYFUNCTION("""COMPUTED_VALUE"""),0.0) -> 0 | T30: =Octobre!G4 -> 0 | V30: =T30/U30 -> #DIV/0! | X30: =Octobre!K4 | Y30: 1600 | Z30: =X30/Y30 -> 0
A31: NOVEMBRE | C31: =IFERROR(__xludf.DUMMYFUNCTION("""COMPUTED_VALUE"""),0.0) -> 0 | D31: =Novembre!C4 -> 0 | E31: 4000 | F31: =D31/E31 -> 0 | G31: =IFERROR(__xludf.DUMMYFUNCTION("""COMPUTED_VALUE"""),44786.039999999986) -> 44786.04 | H31: =Novembre!D4 -> 0 | I31: 50000 | J31: =H31/I31 -> 0 | K31: =IFERROR(__xludf.DUMMYFUNCTION("""COMPUTED_VALUE"""),44033.8) -> 44033.8 | L31: =Novembre!E4 -> 0 | M31: 30000 | N31: =L31/M31 -> 0 | O31: =IFERROR(__xludf.DUMMYFUNCTION("""COMPUTED_VALUE"""),26819.260000000002) -> 26819.26 | P31: =Novembre!F4 -> 0 | Q31: 25000 | R31: =P31/Q31 -> 0 | S31: =IFERROR(__xludf.DUMMYFUNCTION("""COMPUTED_VALUE"""),0.0) -> 0 | T31: =Novembre!G4 -> 0 | V31: =T31/U31 -> #DIV/0! | X31: =Novembre!K4 | Y31: 1600 | Z31: =X31/Y31 -> 0
A32: DÉCEMBRE | C32: =IFERROR(__xludf.DUMMYFUNCTION("""COMPUTED_VALUE"""),0.0) -> 0 | D32: ='Décembre'!C4 -> 0 | E32: 4000 | F32: =D32/E32 -> 0 | G32: =IFERROR(__xludf.DUMMYFUNCTION("""COMPUTED_VALUE"""),38403.28999999999) -> 38403.29 | H32: ='Décembre'!D4 -> 0 | I32: 30000 | J32: =H32/I32 -> 0 | K32: =IFERROR(__xludf.DUMMYFUNCTION("""COMPUTED_VALUE"""),5384.4) -> 5384.4 | L32: ='Décembre'!E4 -> 0 | M32: 12000 | N32: =L32/M32 -> 0 | O32: =IFERROR(__xludf.DUMMYFUNCTION("""COMPUTED_VALUE"""),25596.5) -> 25596.5 | P32: ='Décembre'!F4 -> 0 | Q32: 25000 | R32: =P32/Q32 -> 0 | S32: =IFERROR(__xludf.DUMMYFUNCTION("""COMPUTED_VALUE"""),0.0) -> 0 | T32: ='Décembre'!G4 -> 0 | V32: =T32/U32 -> #DIV/0! | X32: ='Décembre'!K4 | Y32: 1600 | Z32: =X32/Y32 -> 0
A33: Total | C33: =SUM(C21:C32) -> 149047 | D33: =SUM(D21:D32) -> 55700 | E33: =SUM(E21:E32) -> 175000 | F33: =D33/E33 -> 0.31828571 | G33: =SUM(G21:G32) -> 666631.95 | H33: =SUM(H21:H32) -> 161675.3 | I33: =SUM(I21:I32) -> 700000 | J33: =H33/I33 -> 0.23096471 | K33: =SUM(K21:K32) -> 579292.14 | L33: =SUM(L21:L32) -> 138272.67 | M33: =SUM(M21:M32) -> 249000 | N33: =L33/M33 -> 0.55531193 | O33: =SUM(O21:O32) -> 241104.15 | P33: =SUM(P21:P32) -> 104994.75 | Q33: =SUM(Q21:Q32) -> 300000 | R33: =P33/Q33 -> 0.3499825 | S33: =SUM(S21:S32) -> 750 | T33: =SUM(T21:T32) -> 450 | U33: =SUM(U21:U32) -> 0 | V33: =T33/U33 -> #DIV/0! | W33: =SUM(W21:W32) -> 0 | X33: =SUM(X21:X32) -> 0 | Y33: =SUM(Y21:Y32) -> 26000 | Z33: =X33/Y33 -> 0

Sheet Paye
A1: PAIEMENT AFFICHEZ | G1: SOLDE ANNÉE PRÉCÉDANTE
A2: PAYE # | B2: Salaire de base | C2: Commission | D2: Remboursement de dépenses | E2: Fériés | F2: Vacances
G4: MON BONUS ANNUEL
G9: COMMISSION 2025 FACTURÉES | H9: =Objectif!D16*0.05 -> 23679.386
G11: MONTANT EN BANQUE | H11: =H1+H9-C29+I18 -> 23679.386
G15: VACANCES ET FÉRIÉS | H15: VOIR SUR VOTRE TALON DE PAIE
G18: AUTRE (TOTAL) | I18: =SUM(I19:I47) -> 0
J22: =3711.68 -> 3711.68
J23: =Mars!B2-C9 -> 15489.978
A29: SOMME | C29: =SUM(C3:C28) -> 0 | D29: =SUM(D3:D28) -> 0 | E29: =SUM(E3:E28) -> 0 | F29: =SUM(F3:F28) -> 0

Sheet Janvier
B1: Totaux | C1: MÉDIA MULTI-ANNONCEURS | D1: PROMOTIONNEL | E1: DIST. PUBLICITAIRE SOLO | F1: NUMÉRIQUE | G1: APPLICATION | H1: SERVICES IA
A2: Commission | B2: =SUM(G7:G960) -> 7191.034 | C2: =SUMIF(F8:F958,"MÉDIA MULTI-ANNONCEURS",G8:G958) -> 578.5 | D2: =SUMIF(F8:F958,"PROMOTIONNEL",G8:G958) -> 1467.791 | E2: =SUMIF(F8:F958,"DIST. PUBLICITAIRE SOLO",G8:G958) -> 1218.318 | F2: =SUMIF(F8:F958,"AGENCE PUB",G8:G958) -> 3881.425 | G2: =SUMIF(F8:F958,"AGENCE WEB",G8:G958) -> 45 | H2: =SUMIF(F8:F958,"SERVICES IA",G8:G958) -> 0
A4: Vente | B4: =SUM(B8:B960) -> 71910.34 | C4: =SUMIF(F8:F958,"MÉDIA MULTI-ANNONCEURS",B8:B958) -> 5785 | D4: =SUMIF(F8:F958,"PROMOTIONNEL",B8:B958) -> 14677.91 | E4: =SUMIF(F8:F958,"DIST. PUBLICITAIRE SOLO",B8:B958) -> 12183.18 | F4: =SUMIF(F8:F958,"AGENCE PUB",B8:B958) -> 38814.25 | G4: =SUMIF(F8:F958,"AGENCE WEB",B8:B958) -> 450 | H4: =SUMIF(F8:F958,"SERVICES IA",B8:B958) -> 0
A7: CLIENT | B7: TOTAL (AVANT TAXES) | C7: # FACTURE | D7: DATE | E7: REPRÉSENTANT | F7: DÉPARTEMENT | G7: COMMISSION
A8: Capella | B8: 6243.18 | C8: QC-019023 | D8: 46023 | E8: Kim Foster Cunningham | F8: DIST. PUBLICITAIRE SOLO | G8: =B8*0.1 -> 624.318
A9: Entretien DP | B9: 450 | C9: QC-019077 | D9: 46023 | E9: Kim Foster Cunningham | F9: AGENCE PUB | G9: =B9*0.1 -> 45
A10: Super beauté coiffure | B10: 450 | C10: QC-019088 | D10: 46023 | E10: Kim Foster Cunningham | F10: AGENCE PUB | G10: =B10*0.1 -> 45
A11: VR Surmesur | B11: 450 | C11: QC-019090 | D11: 46023 | E11: Kim Foster Cunningham | F11: AGENCE PUB | G11: =B11*0.1 -> 45
A12: Cameron Gestion Radon | B12: 450 | C12: QC-019092 | D12: 46023 | E12: Kim Foster Cunningham | F12: AGENCE PUB | G12: =B12*0.1 -> 45
A13: Paysagement Levasseur | B13: 450 | C13: QC-019101 | D13: 46023 | E13: Kim Foster Cunningham | F13: AGENCE PUB | G13: =B13*0.1 -> 45
A14: Céramique Pissinis | B14: 450 | C14: QC-019105 | D14: 46023 | E14: Kim Foster Cunningham | F14: AGENCE PUB | G14: =B14*0.1 -> 45
A15: Patio Modèle | B15: 450 | C15: QC-019109 | D15: 46023 | E15: Kim Foster Cunningham | F15: AGENCE PUB | G15: =B15*0.1 -> 45
A16: Pro-multiples | B16: 450 | C16: QC-019111 | D16: 46023 | E16: Kim Foster Cunningham | F16: AGENCE PUB | G16: =B16*0.1 -> 45
A17: TRACKZ MOBILITÉ | B17: 450 | C17: QC-019118 | D17: 46023 | E17: Kim Foster Cunningham | F17: AGENCE WEB | G17: =B17*0.1 -> 45
A18: Motorisés de la capitale | B18: 450 | C18: QC-019124 | D18: 46023 | E18: Kim Foster Cunningham | F18: AGENCE PUB | G18: =B18*0.1 -> 45
A19: Transport Multi Vrac | B19: 520 | C19: QC-019141 | D19: 46023 | E19: Kim Foster Cunningham | F19: AGENCE PUB | G19: =B19*0.1 -> 52
... A83: Generaplus | B83: 316.24 | C83: QC-019249 | D83: 46049 | E83: Kim Foster Cunningham | F83: PROMOTIONNEL | G83: =B83*0.1 -> 31.624
G84: =B84*0.1 -> 0
G85: =B85*0.1 -> 0
G86: =B86*0.1 -> 0
G87: =B87*0.1 -> 0
G88: =B88*0.1 -> 0
G89: =B89*0.1 -> 0
G90: =B90*0.1 -> 0
G91: =B91*0.1 -> 0
G92: =B92*0.1 -> 0
G93: =B93*0.1 -> 0
G94: =B94*0.1 -> 0
G95: =B95*0.1 -> 0
... G164: =B164*0.1 -> 0
G165: =B165*0.05 -> 0
G166: =B166*0.05 -> 0
G167: =B167*0.05 -> 0
G168: =B168*0.05 -> 0
G169: =B169*0.05 -> 0
G170: =B170*0.05 -> 0
G171: =B171*0.05 -> 0
G172: =B172*0.05 -> 0
G173: =B173*0.05 -> 0
G174: =B174*0.05 -> 0
...

Sheet Février
B1: Totaux | C1: MÉDIA MULTI-ANNONCEURS | D1: PROMOTIONNEL | E1: DIST. PUBLICITAIRE SOLO | F1: NUMÉRIQUE | G1: APPLICATION | H1: SERVICES IA
A2: Commission | B2: =SUM(G7:G962) -> 13375.099 | C2: =SUMIF(F8:F960,"MÉDIA MULTI-ANNONCEURS",G8:G960) -> 358.5 | D2: =SUMIF(F8:F960,"PROMOTIONNEL",G8:G960) -> 3897.01 | E2: =SUMIF(F8:F960,"DIST. PUBLICITAIRE SOLO",G8:G960) -> 6537.064 | F2: =SUMIF(F8:F960,"AGENCE PUB",G8:G960) -> 2582.525 | G2: =SUMIF(F8:F960,"AGENCE WEB",G8:G960) -> 0 | H2: =SUMIF(F8:F960,"SERVICES IA",G8:G960) -> 0
A4: Vente | B4: =SUM(B8:B962) -> 133750.99 | C4: =SUMIF(F8:F960,"MÉDIA MULTI-ANNONCEURS",B8:B960) -> 3585 | D4: =SUMIF(F8:F960,"PROMOTIONNEL",B8:B960) -> 38970.1 | E4: =SUMIF(F8:F960,"DIST. PUBLICITAIRE SOLO",B8:B960) -> 65370.64 | F4: =SUMIF(F8:F960,"AGENCE PUB",B8:B960) -> 25825.25 | G4: =SUMIF(F8:F960,"AGENCE WEB",B8:B960) -> 0 | H4: =SUMIF(F8:F960,"SERVICES IA",B8:B960) -> 0
A7: CLIENT | B7: TOTAL (AVANT TAXES) | C7: # FACTURE | D7: DATE | E7: REPRÉSENTANT | F7: DÉPARTEMENT | G7: COMMISSION
A8: Jean-Sébastien Lessard | B8: 1595 | C8: QC-019395 | D8: 46059 | E8: Kim Foster Cunningham | F8: MÉDIA MULTI-ANNONCEURS | G8: =B8*0.1 -> 159.5
A9: Transfert Consul | B9: 234.29 | C9: QC-019393 | D9: 46059 | E9: Kim Foster Cunningham | F9: PROMOTIONNEL | G9: =B9*0.1 -> 23.429
A10: Catherine Labrecque Inc. | B10: 1623.23 | C10: QC-019391 | D10: 46059 | E10: Kim Foster Cunningham | F10: DIST. PUBLICITAIRE SOLO | G10: =B10*0.1 -> 162.323
A11: L2 Construction | B11: 160 | C11: QC-019389 | D11: 46059 | E11: Kim Foster Cunningham | F11: PROMOTIONNEL | G11: =B11*0.1 -> 16
A12: Loisirs Lebourgneuf | B12: 660 | C12: QC-019386 | D12: 46059 | E12: Kim Foster Cunningham | F12: PROMOTIONNEL | G12: =B12*0.1 -> 66
A13: Garderie Peluche Clémentine | B13: 663.29 | C13: QC-019385 | D13: 46059 | E13: Kim Foster Cunningham | F13: PROMOTIONNEL | G13: =B13*0.1 -> 66.329
A14: Groupe Domus Construction | B14: 230 | C14: QC-019383 | D14: 46058 | E14: Kim Foster Cunningham | F14: PROMOTIONNEL | G14: =B14*0.1 -> 23
A15: Capella | B15: 6225 | C15: QC-019379 | D15: 46058 | E15: Kim Foster Cunningham | F15: DIST. PUBLICITAIRE SOLO | G15: =B15*0.1 -> 622.5
A16: Pomme Salade inc. | B16: 119 | C16: QC-019373 | D16: 46057 | E16: Kim Foster Cunningham | F16: PROMOTIONNEL | G16: =B16*0.1 -> 11.9
A17: Roxanne Cuisine | B17: 1083 | C17: QC-019359 | D17: 46056 | E17: Kim Foster Cunningham | F17: PROMOTIONNEL | G17: =B17*0.1 -> 108.3
A18: Roxanne Cuisine | B18: 1812.5 | C18: QC-019357 | D18: 46056 | E18: Kim Foster Cunningham | F18: PROMOTIONNEL | G18: =B18*0.1 -> 181.25
A19: VANdredi location inc | B19: 1488 | C19: QC-019353 | D19: 46056 | E19: Kim Foster Cunningham | F19: PROMOTIONNEL | G19: =B19*0.1 -> 148.8
... A78: Perry Wong et Andrew Masson-Wong Century 21 Premier choix | B78: 3361.5 | C78: QC-019490 | D78: 46076 | E78: Kim Foster Cunningham | F78: DIST. PUBLICITAIRE SOLO | G78: =B78*0.1 -> 336.15
G79: =B79*0.1 -> 0
G80: =B80*0.1 -> 0
G81: =B81*0.1 -> 0
G82: =B82*0.1 -> 0
G83: =B83*0.1 -> 0
G84: =B84*0.1 -> 0
G85: =B85*0.1 -> 0
G86: =B86*0.1 -> 0
G87: =B87*0.1 -> 0
G88: =B88*0.1 -> 0
G89: =B89*0.1 -> 0
G90: =B90*0.1 -> 0
... G166: =B166*0.1 -> 0
G167: =B167*0.05 -> 0
G168: =B168*0.05 -> 0
G169: =B169*0.05 -> 0
G170: =B170*0.05 -> 0
G171: =B171*0.05 -> 0
G172: =B172*0.05 -> 0
G173: =B173*0.05 -> 0
G174: =B174*0.05 -> 0
G175: =B175*0.05 -> 0
G176: =B176*0.05 -> 0
...

Sheet Mars
B1: Totaux | C1: MÉDIA MULTI-ANNONCEURS | D1: PROMOTIONNEL | E1: DIST. PUBLICITAIRE SOLO | F1: NUMÉRIQUE | G1: APPLICATION | H1: SERVICES IA
A2: Commission | B2: =SUM(G7:G962) -> 15489.978 | C2: =SUMIF(F8:F960,"MÉDIA MULTI-ANNONCEURS",G8:G960) -> 2107 | D2: =SUMIF(F8:F960,"PROMOTIONNEL",G8:G960) -> 6896.268 | E2: =SUMIF(F8:F960,"DIST. PUBLICITAIRE SOLO",G8:G960) -> 3138.685 | F2: =SUMIF(F8:F960,"AGENCE PUB",G8:G960) -> 3348.025 | G2: =SUMIF(F8:F960,"AGENCE WEB",G8:G960) -> 0 | H2: =SUMIF(F8:F960,"SERVICES IA",G8:G960) -> 0
A4: Vente | B4: =SUM(B8:B962) -> 154899.78 | C4: =SUMIF(F8:F960,"MÉDIA MULTI-ANNONCEURS",B8:B960) -> 21070 | D4: =SUMIF(F8:F960,"PROMOTIONNEL",B8:B960) -> 68962.68 | E4: =SUMIF(F8:F960,"DIST. PUBLICITAIRE SOLO",B8:B960) -> 31386.85 | F4: =SUMIF(F8:F960,"AGENCE PUB",B8:B960) -> 33480.25 | G4: =SUMIF(F8:F960,"AGENCE WEB",B8:B960) -> 0 | H4: =SUMIF(F8:F960,"SERVICES IA",B8:B960) -> 0
A7: CLIENT | B7: TOTAL(AVANTTAXES) | C7: # FACTURE | D7: DATE | E7: REPRÉSENTANT | F7: DÉPARTEMENT | G7: COMMISSION
A8: SST Consultants | B8: 650 | C8: QC-020033 | D8: 46112 | E8: Kim Foster Cunningham | F8: AGENCE PUB | G8: =B8*0.1 -> 65
A9: TRACKZ MOBILITÉ | B9: 850 | C9: QC-020032 | D9: 46112 | E9: Kim Foster Cunningham | F9: AGENCE PUB | G9: =B9*0.1 -> 85
A10: Construction Rénovation RF Inc. | B10: 1350 | C10: QC-020028 | D10: 46112 | E10: Kim Foster Cunningham | F10: AGENCE PUB | G10: =B10*0.1 -> 135
A11: La porte rouge | B11: 475 | C11: QC-020027 | D11: 46112 | E11: Kim Foster Cunningham | F11: AGENCE PUB | G11: =B11*0.1 -> 47.5
A12: Pro-multiples | B12: 150 | C12: QC-020026 | D12: 46112 | E12: Kim Foster Cunningham | F12: AGENCE PUB | G12: =B12*0.1 -> 15
A13: Pro du patio | B13: 475 | C13: QC-020025 | D13: 46112 | E13: Kim Foster Cunningham | F13: AGENCE PUB | G13: =B13*0.1 -> 47.5
A14: Pomme Salade inc. | B14: 1200 | C14: QC-020024 | D14: 46112 | E14: Kim Foster Cunningham | F14: AGENCE PUB | G14: =B14*0.1 -> 120
A15: Paysagement Vert design | B15: 475 | C15: QC-020023 | D15: 46112 | E15: Kim Foster Cunningham | F15: AGENCE PUB | G15: =B15*0.1 -> 47.5
A16: Patio Concept Construction | B16: 962.5 | C16: QC-020022 | D16: 46112 | E16: Kim Foster Cunningham | F16: AGENCE PUB | G16: =B16*0.1 -> 96.25
A17: Groupe NOBELHAUS cuisine festive | B17: 650 | C17: QC-020021 | D17: 46112 | E17: Kim Foster Cunningham | F17: AGENCE PUB | G17: =B17*0.1 -> 65
A18: L'Agence Hypothécaire | B18: 750 | C18: QC-020020 | D18: 46112 | E18: Kim Foster Cunningham | F18: AGENCE PUB | G18: =B18*0.1 -> 75
A19: LOKIA | B19: 2281.25 | C19: QC-020017 | D19: 46112 | E19: Kim Foster Cunningham | F19: AGENCE PUB | G19: =B19*0.1 -> 228.125
... A110: Groupe Lou-Tec | B110: -180 | C110: CN-01102 | D110: 46100 | E110: Kim Foster Cunningham | F110: PROMOTIONNEL | G110: =B110*0.1 -> -18
G111: =B111*0.1 -> 0
G112: =B112*0.1 -> 0
G113: =B113*0.1 -> 0
G114: =B114*0.1 -> 0
G115: =B115*0.1 -> 0
G116: =B116*0.1 -> 0
G117: =B117*0.1 -> 0
G118: =B118*0.1 -> 0
G119: =B119*0.1 -> 0
G120: =B120*0.1 -> 0
G121: =B121*0.1 -> 0
G122: =B122*0.1 -> 0
... G166: =B166*0.1 -> 0
G167: =B167*0.05 -> 0
G168: =B168*0.05 -> 0
G169: =B169*0.05 -> 0
G170: =B170*0.05 -> 0
G171: =B171*0.05 -> 0
G172: =B172*0.05 -> 0
G173: =B173*0.05 -> 0
G174: =B174*0.05 -> 0
G175: =B175*0.05 -> 0
G176: =B176*0.05 -> 0
...

Sheet Avril
B1: Totaux | C1: MÉDIA MULTI-ANNONCEURS | D1: PROMOTIONNEL | E1: DIST. PUBLICITAIRE SOLO | F1: NUMÉRIQUE | G1: APPLICATION | H1: SERVICES IA
A2: Commission | B2: =SUM(G7:G962) -> 11302.661 | C2: =SUMIF(F8:F960,"MÉDIA MULTI-ANNONCEURS",G8:G960) -> 2526 | D2: =SUMIF(F8:F960,"PROMOTIONNEL",G8:G960) -> 3906.461 | E2: =SUMIF(F8:F960,"DIST. PUBLICITAIRE SOLO",G8:G960) -> 2933.2 | F2: =SUMIF(F8:F960,"AGENCE PUB",G8:G960) -> 687.5 | G2: =SUMIF(F8:F960,"AGENCE WEB",G8:G960) -> 0 | H2: =SUMIF(F8:F960,"SERVICES IA",G8:G960) -> 1249.5
A4: Vente | B4: =SUM(B8:B962) -> 113026.61 | C4: =SUMIF(F8:F960,"MÉDIA MULTI-ANNONCEURS",B8:B960) -> 25260 | D4: =SUMIF(F8:F960,"PROMOTIONNEL",B8:B960) -> 39064.61 | E4: =SUMIF(F8:F960,"DIST. PUBLICITAIRE SOLO",B8:B960) -> 29332 | F4: =SUMIF(F8:F960,"AGENCE PUB",B8:B960) -> 6875 | G4: =SUMIF(F8:F960,"AGENCE WEB",B8:B960) -> 0 | H4: =SUMIF(F8:F960,"SERVICES IA",B8:B960) -> 12495
A7: CLIENT | B7: TOTAL (AVANT TAXES) | C7: # FACTURE | D7: DATE | E7: REPRÉSENTANT | F7: DÉPARTEMENT | G7: COMMISSION
A8: Groupe Cabico Inc. | B8: 135.89 | C8: QC-019990 | D8: 46113 | E8: Kim Foster Cunningham | F8: PROMOTIONNEL | G8: =B8*0.1 -> 13.589
A9: Yéti Construction | B9: 325.8 | C9: QC-019981 | D9: 46113 | E9: Kim Foster Cunningham | F9: PROMOTIONNEL | G9: =B9*0.1 -> 32.58
A10: Pomme Salade inc. | B10: 119 | C10: QC-019983 | D10: 46113 | E10: Kim Foster Cunningham | F10: PROMOTIONNEL | G10: =B10*0.1 -> 11.9
A11: Peinture Magog & Orford | B11: 458.65 | C11: QC-020043 | D11: 46114 | E11: Kim Foster Cunningham | F11: DIST. PUBLICITAIRE SOLO | G11: =B11*0.1 -> 45.865
A12: Peinture Magog & Orford | B12: 2707.5 | C12: QC-020040 | D12: 46114 | E12: Kim Foster Cunningham | F12: DIST. PUBLICITAIRE SOLO | G12: =B12*0.1 -> 270.75
A13: Pro-multiples | B13: 776.06 | C13: QC-020052 | D13: 46114 | E13: Kim Foster Cunningham | F13: PROMOTIONNEL | G13: =B13*0.1 -> 77.606
A14: Signature AP | B14: 3966.23 | C14: QC-020049 | D14: 46114 | E14: Kim Foster Cunningham | F14: PROMOTIONNEL | G14: =B14*0.1 -> 396.623
A15: Paysagement Levasseur | B15: 500 | C15: QC-020042 | D15: 46114 | E15: Kim Foster Cunningham | F15: AGENCE PUB | G15: =B15*0.1 -> 50
A16: Macno Construction et rénovation | B16: 4425 | C16: QC-020038 | D16: 46114 | E16: Kim Foster Cunningham | F16: AGENCE PUB | G16: =B16*0.1 -> 442.5
A17: Services Apollo Inc | B17: 1156.2 | C17: QC-020037 | D17: 46114 | E17: Kim Foster Cunningham | F17: DIST. PUBLICITAIRE SOLO | G17: =B17*0.1 -> 115.62
A18: Peinture Antony Soucy | B18: 1156.2 | C18: QC-020036 | D18: 46114 | E18: Kim Foster Cunningham | F18: DIST. PUBLICITAIRE SOLO | G18: =B18*0.1 -> 115.62
A19: Médialliance | B19: 6475 | C19: QC-020035 | D19: 46114 | E19: Kim Foster Cunningham | F19: DIST. PUBLICITAIRE SOLO | G19: =B19*0.1 -> 647.5
... A70: Viva Sgobba | B70: 2566 | C70: QC-020236 | D70: 46132 | E70: Kim Foster Cunningham | F70: DIST. PUBLICITAIRE SOLO | G70: =B70*0.1 -> 256.6
G71: =B71*0.1 -> 0
G72: =B72*0.1 -> 0
G73: =B73*0.1 -> 0
G74: =B74*0.1 -> 0
G75: =B75*0.1 -> 0
G76: =B76*0.1 -> 0
G77: =B77*0.1 -> 0
G78: =B78*0.1 -> 0
G79: =B79*0.1 -> 0
G80: =B80*0.1 -> 0
G81: =B81*0.1 -> 0
G82: =B82*0.1 -> 0
... G166: =B166*0.1 -> 0
G167: =B167*0.05 -> 0
G168: =B168*0.05 -> 0
G169: =B169*0.05 -> 0
G170: =B170*0.05 -> 0
G171: =B171*0.05 -> 0
G172: =B172*0.05 -> 0
G173: =B173*0.05 -> 0
G174: =B174*0.05 -> 0
G175: =B175*0.05 -> 0
G176: =B176*0.05 -> 0
...

Sheet Mai
B1: Totaux | C1: MÉDIA MULTI-ANNONCEURS | D1: PROMOTIONNEL | E1: DIST. PUBLICITAIRE SOLO | F1: NUMÉRIQUE | G1: APPLICATION | H1: SERVICES IA
A2: Commission | B2: =SUM(G7:G962) -> 0 | C2: =SUMIF(F8:F960,"MÉDIA MULTI-ANNONCEURS",G8:G960) -> 0 | D2: =SUMIF(F8:F960,"PROMOTIONNEL",G8:G960) -> 0 | E2: =SUMIF(F8:F960,"DIST. PUBLICITAIRE SOLO",G8:G960) -> 0 | F2: =SUMIF(F8:F960,"AGENCE PUB",G8:G960) -> 0 | G2: =SUMIF(F8:F960,"AGENCE WEB",G8:G960) -> 0 | H2: =SUMIF(F8:F960,"SERVICES IA",G8:G960) -> 0
A4: Vente | B4: =SUM(B8:B962) -> 0 | C4: =SUMIF(F8:F960,"MÉDIA MULTI-ANNONCEURS",B8:B960) -> 0 | D4: =SUMIF(F8:F960,"PROMOTIONNEL",B8:B960) -> 0 | E4: =SUMIF(F8:F960,"DIST. PUBLICITAIRE SOLO",B8:B960) -> 0 | F4: =SUMIF(F8:F960,"AGENCE PUB",B8:B960) -> 0 | G4: =SUMIF(F8:F960,"AGENCE WEB",B8:B960) -> 0 | H4: =SUMIF(F8:F960,"SERVICES IA",B8:B960) -> 0
A7: CLIENT | B7: TOTAL (AVANT TAXES) | C7: # FACTURE | D7: DATE | E7: REPRÉSENTANT | F7: DÉPARTEMENT | G7: COMMISSION
G8: =B8*0.1 -> 0
G9: =B9*0.1 -> 0
G10: =B10*0.1 -> 0
G11: =B11*0.1 -> 0
G12: =B12*0.1 -> 0
G13: =B13*0.1 -> 0
G14: =B14*0.1 -> 0
G15: =B15*0.1 -> 0
G16: =B16*0.1 -> 0
G17: =B17*0.1 -> 0
G18: =B18*0.1 -> 0
G19: =B19*0.1 -> 0
... G166: =B166*0.1 -> 0
G167: =B167*0.05 -> 0
G168: =B168*0.05 -> 0
G169: =B169*0.05 -> 0
G170: =B170*0.05 -> 0
G171: =B171*0.05 -> 0
G172: =B172*0.05 -> 0
G173: =B173*0.05 -> 0
G174: =B174*0.05 -> 0
G175: =B175*0.05 -> 0
G176: =B176*0.05 -> 0
G177: =B177*0.05 -> 0
G178: =B178*0.05 -> 0
... G212: =B212*0.05 -> 0

Sheet Juin
B1: Totaux | C1: MÉDIA MULTI-ANNONCEURS | D1: PROMOTIONNEL | E1: DIST. PUBLICITAIRE SOLO | F1: NUMÉRIQUE | G1: APPLICATION | H1: SERVICES IA
A2: Commission | B2: =SUM(G7:G962) -> 0 | C2: =SUMIF(F8:F960,"MÉDIA MULTI-ANNONCEURS",G8:G960) -> 0 | D2: =SUMIF(F8:F960,"PROMOTIONNEL",G8:G960) -> 0 | E2: =SUMIF(F8:F960,"DIST. PUBLICITAIRE SOLO",G8:G960) -> 0 | F2: =SUMIF(F8:F960,"AGENCE PUB",G8:G960) -> 0 | G2: =SUMIF(F8:F960,"AGENCE WEB",G8:G960) -> 0 | H2: =SUMIF(F8:F960,"SERVICES IA",G8:G960) -> 0
A4: Vente | B4: =SUM(B8:B962) -> 0 | C4: =SUMIF(F8:F960,"MÉDIA MULTI-ANNONCEURS",B8:B960) -> 0 | D4: =SUMIF(F8:F960,"PROMOTIONNEL",B8:B960) -> 0 | E4: =SUMIF(F8:F960,"DIST. PUBLICITAIRE SOLO",B8:B960) -> 0 | F4: =SUMIF(F8:F960,"AGENCE PUB",B8:B960) -> 0 | G4: =SUMIF(F8:F960,"AGENCE WEB",B8:B960) -> 0 | H4: =SUMIF(F8:F960,"SERVICES IA",B8:B960) -> 0
A7: CLIENT | B7: TOTAL (AVANT TAXES) | C7: # FACTURE | D7: DATE | E7: REPRÉSENTANT | F7: DÉPARTEMENT | G7: COMMISSION
G8: =B8*0.1 -> 0
G9: =B9*0.1 -> 0
G10: =B10*0.1 -> 0
G11: =B11*0.1 -> 0
G12: =B12*0.1 -> 0
G13: =B13*0.1 -> 0
G14: =B14*0.1 -> 0
G15: =B15*0.1 -> 0
G16: =B16*0.1 -> 0
G17: =B17*0.1 -> 0
G18: =B18*0.1 -> 0
G19: =B19*0.1 -> 0
... G166: =B166*0.1 -> 0
G167: =B167*0.05 -> 0
G168: =B168*0.05 -> 0
G169: =B169*0.05 -> 0
G170: =B170*0.05 -> 0
G171: =B171*0.05 -> 0
G172: =B172*0.05 -> 0
G173: =B173*0.05 -> 0
G174: =B174*0.05 -> 0
G175: =B175*0.05 -> 0
G176: =B176*0.05 -> 0
G177: =B177*0.05 -> 0
G178: =B178*0.05 -> 0
... G212: =B212*0.05 -> 0

Sheet Juillet
B1: Totaux | C1: MÉDIA MULTI-ANNONCEURS | D1: PROMOTIONNEL | E1: DIST. PUBLICITAIRE SOLO | F1: NUMÉRIQUE | G1: APPLICATION | H1: SERVICES IA
A2: Commission | B2: =SUM(G7:G962) -> 0 | C2: =SUMIF(F8:F960,"MÉDIA MULTI-ANNONCEURS",G8:G960) -> 0 | D2: =SUMIF(F8:F960,"PROMOTIONNEL",G8:G960) -> 0 | E2: =SUMIF(F8:F960,"DIST. PUBLICITAIRE SOLO",G8:G960) -> 0 | F2: =SUMIF(F8:F960,"AGENCE PUB",G8:G960) -> 0 | G2: =SUMIF(F8:F960,"AGENCE WEB",G8:G960) -> 0 | H2: =SUMIF(F8:F960,"SERVICES IA",G8:G960) -> 0
A4: Vente | B4: =SUM(B8:B962) -> 0 | C4: =SUMIF(F8:F960,"MÉDIA MULTI-ANNONCEURS",B8:B960) -> 0 | D4: =SUMIF(F8:F960,"PROMOTIONNEL",B8:B960) -> 0 | E4: =SUMIF(F8:F960,"DIST. PUBLICITAIRE SOLO",B8:B960) -> 0 | F4: =SUMIF(F8:F960,"AGENCE PUB",B8:B960) -> 0 | G4: =SUMIF(F8:F960,"AGENCE WEB",B8:B960) -> 0 | H4: =SUMIF(F8:F960,"SERVICES IA",B8:B960) -> 0
A7: CLIENT | B7: TOTAL (AVANT TAXES) | C7: # FACTURE | D7: DATE | E7: REPRÉSENTANT | F7: DÉPARTEMENT | G7: COMMISSION
G8: =B8*0.1 -> 0
G9: =B9*0.1 -> 0
G10: =B10*0.1 -> 0
G11: =B11*0.1 -> 0
G12: =B12*0.1 -> 0
G13: =B13*0.1 -> 0
G14: =B14*0.1 -> 0
G15: =B15*0.1 -> 0
G16: =B16*0.1 -> 0
G17: =B17*0.1 -> 0
G18: =B18*0.1 -> 0
G19: =B19*0.1 -> 0
... G166: =B166*0.1 -> 0
G167: =B167*0.05 -> 0
G168: =B168*0.05 -> 0
G169: =B169*0.05 -> 0
G170: =B170*0.05 -> 0
G171: =B171*0.05 -> 0
G172: =B172*0.05 -> 0
G173: =B173*0.05 -> 0
G174: =B174*0.05 -> 0
G175: =B175*0.05 -> 0
G176: =B176*0.05 -> 0
G177: =B177*0.05 -> 0
G178: =B178*0.05 -> 0
... G212: =B212*0.05 -> 0

Sheet Août
B1: Totaux | C1: MÉDIA MULTI-ANNONCEURS | D1: PROMOTIONNEL | E1: DIST. PUBLICITAIRE SOLO | F1: NUMÉRIQUE | G1: APPLICATION | H1: SERVICES IA
A2: Commission | B2: =SUM(G7:G962) -> 0 | C2: =SUMIF(F8:F960,"MÉDIA MULTI-ANNONCEURS",G8:G960) -> 0 | D2: =SUMIF(F8:F960,"PROMOTIONNEL",G8:G960) -> 0 | E2: =SUMIF(F8:F960,"DIST. PUBLICITAIRE SOLO",G8:G960) -> 0 | F2: =SUMIF(F8:F960,"AGENCE PUB",G8:G960) -> 0 | G2: =SUMIF(F8:F960,"AGENCE WEB",G8:G960) -> 0 | H2: =SUMIF(F8:F960,"SERVICES IA",G8:G960) -> 0
A4: Vente | B4: =SUM(B8:B962) -> 0 | C4: =SUMIF(F8:F960,"MÉDIA MULTI-ANNONCEURS",B8:B960) -> 0 | D4: =SUMIF(F8:F960,"PROMOTIONNEL",B8:B960) -> 0 | E4: =SUMIF(F8:F960,"DIST. PUBLICITAIRE SOLO",B8:B960) -> 0 | F4: =SUMIF(F8:F960,"AGENCE PUB",B8:B960) -> 0 | G4: =SUMIF(F8:F960,"AGENCE WEB",B8:B960) -> 0 | H4: =SUMIF(F8:F960,"SERVICES IA",B8:B960) -> 0
A7: CLIENT | B7: TOTAL (AVANT TAXES) | C7: # FACTURE | D7: DATE | E7: REPRÉSENTANT | F7: DÉPARTEMENT | G7: COMMISSION
G8: =B8*0.1 -> 0
G9: =B9*0.1 -> 0
G10: =B10*0.1 -> 0
G11: =B11*0.1 -> 0
G12: =B12*0.1 -> 0
G13: =B13*0.1 -> 0
G14: =B14*0.1 -> 0
G15: =B15*0.1 -> 0
G16: =B16*0.1 -> 0
G17: =B17*0.1 -> 0
G18: =B18*0.1 -> 0
G19: =B19*0.1 -> 0
... G166: =B166*0.1 -> 0
G167: =B167*0.05 -> 0
G168: =B168*0.05 -> 0
G169: =B169*0.05 -> 0
G170: =B170*0.05 -> 0
G171: =B171*0.05 -> 0
G172: =B172*0.05 -> 0
G173: =B173*0.05 -> 0
G174: =B174*0.05 -> 0
G175: =B175*0.05 -> 0
G176: =B176*0.05 -> 0
G177: =B177*0.05 -> 0
G178: =B178*0.05 -> 0
... G212: =B212*0.05 -> 0

Sheet Septembre
B1: Totaux | C1: MÉDIA MULTI-ANNONCEURS | D1: PROMOTIONNEL | E1: DIST. PUBLICITAIRE SOLO | F1: NUMÉRIQUE | G1: APPLICATION | H1: SERVICES IA
A2: Commission | B2: =SUM(G7:G962) -> 0 | C2: =SUMIF(F8:F960,"MÉDIA MULTI-ANNONCEURS",G8:G960) -> 0 | D2: =SUMIF(F8:F960,"PROMOTIONNEL",G8:G960) -> 0 | E2: =SUMIF(F8:F960,"DIST. PUBLICITAIRE SOLO",G8:G960) -> 0 | F2: =SUMIF(F8:F960,"AGENCE PUB",G8:G960) -> 0 | G2: =SUMIF(F8:F960,"AGENCE WEB",G8:G960) -> 0 | H2: =SUMIF(F8:F960,"SERVICES IA",G8:G960) -> 0
A4: Vente | B4: =SUM(B8:B962) -> 0 | C4: =SUMIF(F8:F960,"MÉDIA MULTI-ANNONCEURS",B8:B960) -> 0 | D4: =SUMIF(F8:F960,"PROMOTIONNEL",B8:B960) -> 0 | E4: =SUMIF(F8:F960,"DIST. PUBLICITAIRE SOLO",B8:B960) -> 0 | F4: =SUMIF(F8:F960,"AGENCE PUB",B8:B960) -> 0 | G4: =SUMIF(F8:F960,"AGENCE WEB",B8:B960) -> 0 | H4: =SUMIF(F8:F960,"SERVICES IA",B8:B960) -> 0
A7: CLIENT | B7: TOTAL (AVANT TAXES) | C7: # FACTURE | D7: DATE | E7: REPRÉSENTANT | F7: DÉPARTEMENT | G7: COMMISSION
G8: =B8*0.1 -> 0
G9: =B9*0.1 -> 0
G10: =B10*0.1 -> 0
G11: =B11*0.1 -> 0
G12: =B12*0.1 -> 0
G13: =B13*0.1 -> 0
G14: =B14*0.1 -> 0
G15: =B15*0.1 -> 0
G16: =B16*0.1 -> 0
G17: =B17*0.1 -> 0
G18: =B18*0.1 -> 0
G19: =B19*0.1 -> 0
... G166: =B166*0.1 -> 0
G167: =B167*0.05 -> 0
G168: =B168*0.05 -> 0
G169: =B169*0.05 -> 0
G170: =B170*0.05 -> 0
G171: =B171*0.05 -> 0
G172: =B172*0.05 -> 0
G173: =B173*0.05 -> 0
G174: =B174*0.05 -> 0
G175: =B175*0.05 -> 0
G176: =B176*0.05 -> 0
G177: =B177*0.05 -> 0
G178: =B178*0.05 -> 0
... G212: =B212*0.05 -> 0

Sheet Octobre
B1: Totaux | C1: MÉDIA MULTI-ANNONCEURS | D1: PROMOTIONNEL | E1: DIST. PUBLICITAIRE SOLO | F1: NUMÉRIQUE | G1: APPLICATION | H1: SERVICES IA
A2: Commission | B2: =SUM(G7:G962) -> 0 | C2: =SUMIF(F8:F960,"MÉDIA MULTI-ANNONCEURS",G8:G960) -> 0 | D2: =SUMIF(F8:F960,"PROMOTIONNEL",G8:G960) -> 0 | E2: =SUMIF(F8:F960,"DIST. PUBLICITAIRE SOLO",G8:G960) -> 0 | F2: =SUMIF(F8:F960,"AGENCE PUB",G8:G960) -> 0 | G2: =SUMIF(F8:F960,"AGENCE WEB",G8:G960) -> 0 | H2: =SUMIF(F8:F960,"SERVICES IA",G8:G960) -> 0
A4: Vente | B4: =SUM(B8:B962) -> 0 | C4: =SUMIF(F8:F960,"MÉDIA MULTI-ANNONCEURS",B8:B960) -> 0 | D4: =SUMIF(F8:F960,"PROMOTIONNEL",B8:B960) -> 0 | E4: =SUMIF(F8:F960,"DIST. PUBLICITAIRE SOLO",B8:B960) -> 0 | F4: =SUMIF(F8:F960,"AGENCE PUB",B8:B960) -> 0 | G4: =SUMIF(F8:F960,"AGENCE WEB",B8:B960) -> 0 | H4: =SUMIF(F8:F960,"SERVICES IA",B8:B960) -> 0
A7: CLIENT | B7: TOTAL (AVANT TAXES) | C7: # FACTURE | D7: DATE | E7: REPRÉSENTANT | F7: DÉPARTEMENT | G7: COMMISSION
G8: =B8*0.1 -> 0
G9: =B9*0.1 -> 0
G10: =B10*0.1 -> 0
G11: =B11*0.1 -> 0
G12: =B12*0.1 -> 0
G13: =B13*0.1 -> 0
G14: =B14*0.1 -> 0
G15: =B15*0.1 -> 0
G16: =B16*0.1 -> 0
G17: =B17*0.1 -> 0
G18: =B18*0.1 -> 0
G19: =B19*0.1 -> 0
... G166: =B166*0.1 -> 0
G167: =B167*0.05 -> 0
G168: =B168*0.05 -> 0
G169: =B169*0.05 -> 0
G170: =B170*0.05 -> 0
G171: =B171*0.05 -> 0
G172: =B172*0.05 -> 0
G173: =B173*0.05 -> 0
G174: =B174*0.05 -> 0
G175: =B175*0.05 -> 0
G176: =B176*0.05 -> 0
G177: =B177*0.05 -> 0
G178: =B178*0.05 -> 0
... G212: =B212*0.05 -> 0

Sheet Novembre
B1: Totaux | C1: MÉDIA MULTI-ANNONCEURS | D1: PROMOTIONNEL | E1: DIST. PUBLICITAIRE SOLO | F1: NUMÉRIQUE | G1: APPLICATION | H1: SERVICES IA
A2: Commission | B2: =SUM(G7:G962) -> 0 | C2: =SUMIF(F8:F960,"MÉDIA MULTI-ANNONCEURS",G8:G960) -> 0 | D2: =SUMIF(F8:F960,"PROMOTIONNEL",G8:G960) -> 0 | E2: =SUMIF(F8:F960,"DIST. PUBLICITAIRE SOLO",G8:G960) -> 0 | F2: =SUMIF(F8:F960,"AGENCE PUB",G8:G960) -> 0 | G2: =SUMIF(F8:F960,"AGENCE WEB",G8:G960) -> 0 | H2: =SUMIF(F8:F960,"SERVICES IA",G8:G960) -> 0
A4: Vente | B4: =SUM(B8:B962) -> 0 | C4: =SUMIF(F8:F960,"MÉDIA MULTI-ANNONCEURS",B8:B960) -> 0 | D4: =SUMIF(F8:F960,"PROMOTIONNEL",B8:B960) -> 0 | E4: =SUMIF(F8:F960,"DIST. PUBLICITAIRE SOLO",B8:B960) -> 0 | F4: =SUMIF(F8:F960,"AGENCE PUB",B8:B960) -> 0 | G4: =SUMIF(F8:F960,"AGENCE WEB",B8:B960) -> 0 | H4: =SUMIF(F8:F960,"SERVICES IA",B8:B960) -> 0
A7: CLIENT | B7: TOTAL (AVANT TAXES) | C7: # FACTURE | D7: DATE | E7: REPRÉSENTANT | F7: DÉPARTEMENT | G7: COMMISSION
G8: =B8*0.1 -> 0
G9: =B9*0.1 -> 0
G10: =B10*0.1 -> 0
G11: =B11*0.1 -> 0
G12: =B12*0.1 -> 0
G13: =B13*0.1 -> 0
G14: =B14*0.1 -> 0
G15: =B15*0.1 -> 0
G16: =B16*0.1 -> 0
G17: =B17*0.1 -> 0
G18: =B18*0.1 -> 0
G19: =B19*0.1 -> 0
... G166: =B166*0.1 -> 0
G167: =B167*0.05 -> 0
G168: =B168*0.05 -> 0
G169: =B169*0.05 -> 0
G170: =B170*0.05 -> 0
G171: =B171*0.05 -> 0
G172: =B172*0.05 -> 0
G173: =B173*0.05 -> 0
G174: =B174*0.05 -> 0
G175: =B175*0.05 -> 0
G176: =B176*0.05 -> 0
G177: =B177*0.05 -> 0
G178: =B178*0.05 -> 0
... G212: =B212*0.05 -> 0

Sheet Décembre
B1: Totaux | C1: MÉDIA MULTI-ANNONCEURS | D1: PROMOTIONNEL | E1: DIST. PUBLICITAIRE SOLO | F1: NUMÉRIQUE | G1: APPLICATION | H1: SERVICES IA
A2: Commission | B2: =SUM(G7:G962) -> 0 | C2: =SUMIF(F8:F960,"MÉDIA MULTI-ANNONCEURS",G8:G960) -> 0 | D2: =SUMIF(F8:F960,"PROMOTIONNEL",G8:G960) -> 0 | E2: =SUMIF(F8:F960,"DIST. PUBLICITAIRE SOLO",G8:G960) -> 0 | F2: =SUMIF(F8:F960,"AGENCE PUB",G8:G960) -> 0 | G2: =SUMIF(F8:F960,"AGENCE WEB",G8:G960) -> 0 | H2: =SUMIF(F8:F960,"SERVICES IA",G8:G960) -> 0
A4: Vente | B4: =SUM(B8:B962) -> 0 | C4: =SUMIF(F8:F960,"MÉDIA MULTI-ANNONCEURS",B8:B960) -> 0 | D4: =SUMIF(F8:F960,"PROMOTIONNEL",B8:B960) -> 0 | E4: =SUMIF(F8:F960,"DIST. PUBLICITAIRE SOLO",B8:B960) -> 0 | F4: =SUMIF(F8:F960,"AGENCE PUB",B8:B960) -> 0 | G4: =SUMIF(F8:F960,"AGENCE WEB",B8:B960) -> 0 | H4: =SUMIF(F8:F960,"SERVICES IA",B8:B960) -> 0
A7: CLIENT | B7: TOTAL (AVANT TAXES) | C7: # FACTURE | D7: DATE | E7: REPRÉSENTANT | F7: DÉPARTEMENT | G7: COMMISSION
G8: =B8*0.1 -> 0
G9: =B9*0.1 -> 0
G10: =B10*0.1 -> 0
G11: =B11*0.1 -> 0
G12: =B12*0.1 -> 0
G13: =B13*0.1 -> 0
G14: =B14*0.1 -> 0
G15: =B15*0.1 -> 0
G16: =B16*0.1 -> 0
G17: =B17*0.1 -> 0
G18: =B18*0.1 -> 0
G19: =B19*0.1 -> 0
... G166: =B166*0.1 -> 0
G167: =B167*0.05 -> 0
G168: =B168*0.05 -> 0
G169: =B169*0.05 -> 0
G170: =B170*0.05 -> 0
G171: =B171*0.05 -> 0
G172: =B172*0.05 -> 0
G173: =B173*0.05 -> 0
G174: =B174*0.05 -> 0
G175: =B175*0.05 -> 0
G176: =B176*0.05 -> 0
G177: =B177*0.05 -> 0
G178: =B178*0.05 -> 0
... G212: =B212*0.05 -> 0
